Workbook

Sheet PETUNJUK
B1: CARA PAKAI Bformat.xlsx
B3: 1. Laporan Bendahara Pengeluaran (BPG)
B4: Sumber data: file 'Rekapitulasi LPJ Bendahara Pengeluaran Tingkat KPPN', sheet 'Data'.
B5: a. Buka file Rekapitulasi mentahnya, klik sheet 'Data'.
B6: b. Klik sel A1, lalu tekan Ctrl+A (pilih semua isi sheet).
B7: c. Tekan Ctrl+C (copy).
B8: d. Di file ini, buka sheet 'Paste BPG', klik sel A1 (sel kuning bertanda merah), lalu tekan Ctrl+V (paste).
B9: e. Selesai -- sheet 'Report' yang sesuai otomatis terhitung ulang.
B11: 2. Laporan Bendahara Penerimaan (BPN)
B12: Sumber data: file 'Rekapitulasi LPJ Bendahara Penerimaan Tingkat KPPN', sheet 'Data'.
B13: a. Buka file Rekapitulasi mentahnya, klik sheet 'Data'.
B14: b. Klik sel A1, lalu tekan Ctrl+A (pilih semua isi sheet).
... B29: Kalau ada Satker baru yang muncul di data KPPN tapi belum ada barisnya di sheet Report, baris itu perlu ditambahkan manual (bukan otomatis).

Sheet Report BPG
C1: DAFTAR LPJ PENGELUARAN
C2: BULAN JUNI TAHUN 2026 | M2: =C2 -> BULAN JUNI TAHUN 2026
A3: KPPN BANDUNG II (095)
A4: NO | B4: KODE SATKER | C4: NAMA SATKER | D4: SALDO MENURUT BUKU PEMBANTU | J4: UANG PERSEDIAAN
D5: BP UP | E5: BP LS BENDAHARA | F5: BP PAJAK | G5: BP HIBAH | H5: BP LAIN-LAIN | I5: JUMLAH | J5: SALDO | K5: KWITANSI | L5: JUMLAH
B7: 005 | C7: MAHKAMAH AGUNG | D7: =SUM(D8+D9+D10+D11+D12+D13+D14+D15+D16+D17+D18+D19+D20+D21+D22+D23+D24+D25+D26+D27) -> 0 | E7: =SUM(E8+E9+E10+E11+E12+E13+E14+E15+E16+E17+E18+E19+E20+E21+E22+E23+E24+E25+E26+E27) -> 0 | F7: =SUM(F8+F9+F10+F11+F12+F13+F14+F15+F16+F17+F18+F19+F20+F21+F22+F23+F24+F25+F26+F27) -> 0 | G7: =SUM(G8+G9+G10+G11+G12+G13+G14+G15+G16+G17+G18+G19+G20+G21+G22+G23+G24+G25+G26+G27) -> 0 | H7: =SUM(H8+H9+H10+H11+H12+H13+H14+H15+H16+H17+H18+H19+H20+H21+H22+H23+H24+H25+H26+H27) -> 0 | I7: =SUM(D7+E7+F7+G7+H7) -> 0 | J7: =SUM(J8+J9+J10+J11+J12+J13+J14+J15+J16+J17+J18+J19+J20+J21+J22+J23+J24+J25+J26+J27) -> 0 | K7: =SUM(K8+K9+K10+K11+K12+K13+K14+K15+K16+K17+K18+K19+K20+K21+K22+K23+K24+K25+K26+K27) -> 0 | L7: =J7+K7 -> 0
A8: 1 | B8: 097500 | C8: PENGADILAN TINGGI BANDUNG | D8: =IFERROR(VALUE(SUBSTITUTE(INDEX('Paste BPG'!$A:$Z,MATCH($B8,'Paste BPG'!$C:$C,0),MATCH("BP UP/TUP",'Paste BPG'!$3:$3,0)),".","")),0) -> 0 | E8: =IFERROR(VALUE(SUBSTITUTE(INDEX('Paste BPG'!$A:$Z,MATCH($B8,'Paste BPG'!$C:$C,0),MATCH("BP LS BENDAHARA",'Paste BPG'!$3:$3,0)),".","")),0) -> 0 | F8: =IFERROR(VALUE(SUBSTITUTE(INDEX('Paste BPG'!$A:$Z,MATCH($B8,'Paste BPG'!$C:$C,0),MATCH("BP PAJAK",'Paste BPG'!$3:$3,0)),".","")),0) -> 0 | G8: =IFERROR(VALUE(SUBSTITUTE(INDEX('Paste BPG'!$A:$Z,MATCH($B8,'Paste BPG'!$C:$C,0),MATCH("BP HIBAH",'Paste BPG'!$3:$3,0)),".","")),0) -> 0 | H8: =IFERROR(VALUE(SUBSTITUTE(INDEX('Paste BPG'!$A:$Z,MATCH($B8,'Paste BPG'!$C:$C,0),MATCH("BP LAIN-LAIN",'Paste BPG'!$3:$3,0)),".","")),0) -> 0 | I8: =D8+E8+F8+G8+H8 -> 0 | J8: =D8 -> 0 | K8: =IFERROR(VALUE(SUBSTITUTE(INDEX('Paste BPG'!$A:$Z,MATCH($B8,'Paste BPG'!$C:$C,0),MATCH("KUITANSI",'Paste BPG'!$3:$3,0)),".","")),0) -> 0 | L8: =J8+K8 -> 0
A9: 2 | B9: 097514 | C9: PENGADILAN NEGERI BANDUNG | D9: =IFERROR(VALUE(SUBSTITUTE(INDEX('Paste BPG'!$A:$Z,MATCH($B9,'Paste BPG'!$C:$C,0),MATCH("BP UP/TUP",'Paste BPG'!$3:$3,0)),".","")),0) -> 0 | E9: =IFERROR(VALUE(SUBSTITUTE(INDEX('Paste BPG'!$A:$Z,MATCH($B9,'Paste BPG'!$C:$C,0),MATCH("BP LS BENDAHARA",'Paste BPG'!$3:$3,0)),".","")),0) -> 0 | F9: =IFERROR(VALUE(SUBSTITUTE(INDEX('Paste BPG'!$A:$Z,MATCH($B9,'Paste BPG'!$C:$C,0),MATCH("BP PAJAK",'Paste BPG'!$3:$3,0)),".","")),0) -> 0 | G9: =IFERROR(VALUE(SUBSTITUTE(INDEX('Paste BPG'!$A:$Z,MATCH($B9,'Paste BPG'!$C:$C,0),MATCH("BP HIBAH",'Paste BPG'!$3:$3,0)),".","")),0) -> 0 | H9: =IFERROR(VALUE(SUBSTITUTE(INDEX('Paste BPG'!$A:$Z,MATCH($B9,'Paste BPG'!$C:$C,0),MATCH("BP LAIN-LAIN",'Paste BPG'!$3:$3,0)),".","")),0) -> 0 | I9: =D9+E9+F9+G9+H9 -> 0 | J9: =D9 -> 0 | K9: =IFERROR(VALUE(SUBSTITUTE(INDEX('Paste BPG'!$A:$Z,MATCH($B9,'Paste BPG'!$C:$C,0),MATCH("KUITANSI",'Paste BPG'!$3:$3,0)),".","")),0) -> 0 | L9: =J9+K9 -> 0
A10: 3 | B10: 099067 | C10: PENGADILAN TINGGI BANDUNG | D10: =IFERROR(VALUE(SUBSTITUTE(INDEX('Paste BPG'!$A:$Z,MATCH($B10,'Paste BPG'!$C:$C,0),MATCH("BP UP/TUP",'Paste BPG'!$3:$3,0)),".","")),0) -> 0 | E10: =IFERROR(VALUE(SUBSTITUTE(INDEX('Paste BPG'!$A:$Z,MATCH($B10,'Paste BPG'!$C:$C,0),MATCH("BP LS BENDAHARA",'Paste BPG'!$3:$3,0)),".","")),0) -> 0 | F10: =IFERROR(VALUE(SUBSTITUTE(INDEX('Paste BPG'!$A:$Z,MATCH($B10,'Paste BPG'!$C:$C,0),MATCH("BP PAJAK",'Paste BPG'!$3:$3,0)),".","")),0) -> 0 | G10: =IFERROR(VALUE(SUBSTITUTE(INDEX('Paste BPG'!$A:$Z,MATCH($B10,'Paste BPG'!$C:$C,0),MATCH("BP HIBAH",'Paste BPG'!$3:$3,0)),".","")),0) -> 0 | H10: =IFERROR(VALUE(SUBSTITUTE(INDEX('Paste BPG'!$A:$Z,MATCH($B10,'Paste BPG'!$C:$C,0),MATCH("BP LAIN-LAIN",'Paste BPG'!$3:$3,0)),".","")),0) -> 0 | I10: =D10+E10+F10+G10+H10 -> 0 | J10: =D10 -> 0 | K10: =IFERROR(VALUE(SUBSTITUTE(INDEX('Paste BPG'!$A:$Z,MATCH($B10,'Paste BPG'!$C:$C,0),MATCH("KUITANSI",'Paste BPG'!$3:$3,0)),".","")),0) -> 0 | L10: =J10+K10 -> 0
A11: 4 | B11: 099068 | C11: PENGADILAN NEGERI BANDUNG | D11: =IFERROR(VALUE(SUBSTITUTE(INDEX('Paste BPG'!$A:$Z,MATCH($B11,'Paste BPG'!$C:$C,0),MATCH("BP UP/TUP",'Paste BPG'!$3:$3,0)),".","")),0) -> 0 | E11: =IFERROR(VALUE(SUBSTITUTE(INDEX('Paste BPG'!$A:$Z,MATCH($B11,'Paste BPG'!$C:$C,0),MATCH("BP LS BENDAHARA",'Paste BPG'!$3:$3,0)),".","")),0) -> 0 | F11: =IFERROR(VALUE(SUBSTITUTE(INDEX('Paste BPG'!$A:$Z,MATCH($B11,'Paste BPG'!$C:$C,0),MATCH("BP PAJAK",'Paste BPG'!$3:$3,0)),".","")),0) -> 0 | G11: =IFERROR(VALUE(SUBSTITUTE(INDEX('Paste BPG'!$A:$Z,MATCH($B11,'Paste BPG'!$C:$C,0),MATCH("BP HIBAH",'Paste BPG'!$3:$3,0)),".","")),0) -> 0 | H11: =IFERROR(VALUE(SUBSTITUTE(INDEX('Paste BPG'!$A:$Z,MATCH($B11,'Paste BPG'!$C:$C,0),MATCH("BP LAIN-LAIN",'Paste BPG'!$3:$3,0)),".","")),0) -> 0 | I11: =D11+E11+F11+G11+H11 -> 0 | J11: =D11 -> 0 | K11: =IFERROR(VALUE(SUBSTITUTE(INDEX('Paste BPG'!$A:$Z,MATCH($B11,'Paste BPG'!$C:$C,0),MATCH("KUITANSI",'Paste BPG'!$3:$3,0)),".","")),0) -> 0 | L11: =J11+K11 -> 0
A12: 5 | B12: 308166 | C12: PENGADILAN TINGGI AGAMA BANDUNG | D12: =IFERROR(VALUE(SUBSTITUTE(INDEX('Paste BPG'!$A:$Z,MATCH($B12,'Paste BPG'!$C:$C,0),MATCH("BP UP/TUP",'Paste BPG'!$3:$3,0)),".","")),0) -> 0 | E12: =IFERROR(VALUE(SUBSTITUTE(INDEX('Paste BPG'!$A:$Z,MATCH($B12,'Paste BPG'!$C:$C,0),MATCH("BP LS BENDAHARA",'Paste BPG'!$3:$3,0)),".","")),0) -> 0 | F12: =IFERROR(VALUE(SUBSTITUTE(INDEX('Paste BPG'!$A:$Z,MATCH($B12,'Paste BPG'!$C:$C,0),MATCH("BP PAJAK",'Paste BPG'!$3:$3,0)),".","")),0) -> 0 | G12: =IFERROR(VALUE(SUBSTITUTE(INDEX('Paste BPG'!$A:$Z,MATCH($B12,'Paste BPG'!$C:$C,0),MATCH("BP HIBAH",'Paste BPG'!$3:$3,0)),".","")),0) -> 0 | H12: =IFERROR(VALUE(SUBSTITUTE(INDEX('Paste BPG'!$A:$Z,MATCH($B12,'Paste BPG'!$C:$C,0),MATCH("BP LAIN-LAIN",'Paste BPG'!$3:$3,0)),".","")),0) -> 0 | I12: =D12+E12+F12+G12+H12 -> 0 | J12: =D12 -> 0 | K12: =IFERROR(VALUE(SUBSTITUTE(INDEX('Paste BPG'!$A:$Z,MATCH($B12,'Paste BPG'!$C:$C,0),MATCH("KUITANSI",'Paste BPG'!$3:$3,0)),".","")),0) -> 0 | L12: =J12+K12 -> 0
A13: 6 | B13: 309124 | C13: PENGADILAN TINGGI AGAMA BANDUNG | D13: =IFERROR(VALUE(SUBSTITUTE(INDEX('Paste BPG'!$A:$Z,MATCH($B13,'Paste BPG'!$C:$C,0),MATCH("BP UP/TUP",'Paste BPG'!$3:$3,0)),".","")),0) -> 0 | E13: =IFERROR(VALUE(SUBSTITUTE(INDEX('Paste BPG'!$A:$Z,MATCH($B13,'Paste BPG'!$C:$C,0),MATCH("BP LS BENDAHARA",'Paste BPG'!$3:$3,0)),".","")),0) -> 0 | F13: =IFERROR(VALUE(SUBSTITUTE(INDEX('Paste BPG'!$A:$Z,MATCH($B13,'Paste BPG'!$C:$C,0),MATCH("BP PAJAK",'Paste BPG'!$3:$3,0)),".","")),0) -> 0 | G13: =IFERROR(VALUE(SUBSTITUTE(INDEX('Paste BPG'!$A:$Z,MATCH($B13,'Paste BPG'!$C:$C,0),MATCH("BP HIBAH",'Paste BPG'!$3:$3,0)),".","")),0) -> 0 | H13: =IFERROR(VALUE(SUBSTITUTE(INDEX('Paste BPG'!$A:$Z,MATCH($B13,'Paste BPG'!$C:$C,0),MATCH("BP LAIN-LAIN",'Paste BPG'!$3:$3,0)),".","")),0) -> 0 | I13: =D13+E13+F13+G13+H13 -> 0 | J13: =D13 -> 0 | K13: =IFERROR(VALUE(SUBSTITUTE(INDEX('Paste BPG'!$A:$Z,MATCH($B13,'Paste BPG'!$C:$C,0),MATCH("KUITANSI",'Paste BPG'!$3:$3,0)),".","")),0) -> 0 | L13: =J13+K13 -> 0
A14: 7 | B14: 400483 | C14: PENGADILAN NEGERI BALE BANDUNG | D14: =IFERROR(VALUE(SUBSTITUTE(INDEX('Paste BPG'!$A:$Z,MATCH($B14,'Paste BPG'!$C:$C,0),MATCH("BP UP/TUP",'Paste BPG'!$3:$3,0)),".","")),0) -> 0 | E14: =IFERROR(VALUE(SUBSTITUTE(INDEX('Paste BPG'!$A:$Z,MATCH($B14,'Paste BPG'!$C:$C,0),MATCH("BP LS BENDAHARA",'Paste BPG'!$3:$3,0)),".","")),0) -> 0 | F14: =IFERROR(VALUE(SUBSTITUTE(INDEX('Paste BPG'!$A:$Z,MATCH($B14,'Paste BPG'!$C:$C,0),MATCH("BP PAJAK",'Paste BPG'!$3:$3,0)),".","")),0) -> 0 | G14: =IFERROR(VALUE(SUBSTITUTE(INDEX('Paste BPG'!$A:$Z,MATCH($B14,'Paste BPG'!$C:$C,0),MATCH("BP HIBAH",'Paste BPG'!$3:$3,0)),".","")),0) -> 0 | H14: =IFERROR(VALUE(SUBSTITUTE(INDEX('Paste BPG'!$A:$Z,MATCH($B14,'Paste BPG'!$C:$C,0),MATCH("BP LAIN-LAIN",'Paste BPG'!$3:$3,0)),".","")),0) -> 0 | I14: =D14+E14+F14+G14+H14 -> 0 | J14: =D14 -> 0 | K14: =IFERROR(VALUE(SUBSTITUTE(INDEX('Paste BPG'!$A:$Z,MATCH($B14,'Paste BPG'!$C:$C,0),MATCH("KUITANSI",'Paste BPG'!$3:$3,0)),".","")),0) -> 0 | L14: =J14+K14 -> 0
A15: 8 | B15: 400484 | C15: PENGADILAN NEGERI BALE BANDUNG | D15: =IFERROR(VALUE(SUBSTITUTE(INDEX('Paste BPG'!$A:$Z,MATCH($B15,'Paste BPG'!$C:$C,0),MATCH("BP UP/TUP",'Paste BPG'!$3:$3,0)),".","")),0) -> 0 | E15: =IFERROR(VALUE(SUBSTITUTE(INDEX('Paste BPG'!$A:$Z,MATCH($B15,'Paste BPG'!$C:$C,0),MATCH("BP LS BENDAHARA",'Paste BPG'!$3:$3,0)),".","")),0) -> 0 | F15: =IFERROR(VALUE(SUBSTITUTE(INDEX('Paste BPG'!$A:$Z,MATCH($B15,'Paste BPG'!$C:$C,0),MATCH("BP PAJAK",'Paste BPG'!$3:$3,0)),".","")),0) -> 0 | G15: =IFERROR(VALUE(SUBSTITUTE(INDEX('Paste BPG'!$A:$Z,MATCH($B15,'Paste BPG'!$C:$C,0),MATCH("BP HIBAH",'Paste BPG'!$3:$3,0)),".","")),0) -> 0 | H15: =IFERROR(VALUE(SUBSTITUTE(INDEX('Paste BPG'!$A:$Z,MATCH($B15,'Paste BPG'!$C:$C,0),MATCH("BP LAIN-LAIN",'Paste BPG'!$3:$3,0)),".","")),0) -> 0 | I15: =D15+E15+F15+G15+H15 -> 0 | J15: =D15 -> 0 | K15: =IFERROR(VALUE(SUBSTITUTE(INDEX('Paste BPG'!$A:$Z,MATCH($B15,'Paste BPG'!$C:$C,0),MATCH("KUITANSI",'Paste BPG'!$3:$3,0)),".","")),0) -> 0 | L15: =J15+K15 -> 0
A16: 9 | B16: 400662 | C16: PENGADILAN AGAMA BANDUNG | D16: =IFERROR(VALUE(SUBSTITUTE(INDEX('Paste BPG'!$A:$Z,MATCH($B16,'Paste BPG'!$C:$C,0),MATCH("BP UP/TUP",'Paste BPG'!$3:$3,0)),".","")),0) -> 0 | E16: =IFERROR(VALUE(SUBSTITUTE(INDEX('Paste BPG'!$A:$Z,MATCH($B16,'Paste BPG'!$C:$C,0),MATCH("BP LS BENDAHARA",'Paste BPG'!$3:$3,0)),".","")),0) -> 0 | F16: =IFERROR(VALUE(SUBSTITUTE(INDEX('Paste BPG'!$A:$Z,MATCH($B16,'Paste BPG'!$C:$C,0),MATCH("BP PAJAK",'Paste BPG'!$3:$3,0)),".","")),0) -> 0 | G16: =IFERROR(VALUE(SUBSTITUTE(INDEX('Paste BPG'!$A:$Z,MATCH($B16,'Paste BPG'!$C:$C,0),MATCH("BP HIBAH",'Paste BPG'!$3:$3,0)),".","")),0) -> 0 | H16: =IFERROR(VALUE(SUBSTITUTE(INDEX('Paste BPG'!$A:$Z,MATCH($B16,'Paste BPG'!$C:$C,0),MATCH("BP LAIN-LAIN",'Paste BPG'!$3:$3,0)),".","")),0) -> 0 | I16: =D16+E16+F16+G16+H16 -> 0 | J16: =D16 -> 0 | K16: =IFERROR(VALUE(SUBSTITUTE(INDEX('Paste BPG'!$A:$Z,MATCH($B16,'Paste BPG'!$C:$C,0),MATCH("KUITANSI",'Paste BPG'!$3:$3,0)),".","")),0) -> 0 | L16: =J16+K16 -> 0
A17: 10 | B17: 400663 | C17: PENGADILAN AGAMA BANDUNG | D17: =IFERROR(VALUE(SUBSTITUTE(INDEX('Paste BPG'!$A:$Z,MATCH($B17,'Paste BPG'!$C:$C,0),MATCH("BP UP/TUP",'Paste BPG'!$3:$3,0)),".","")),0) -> 0 | E17: =IFERROR(VALUE(SUBSTITUTE(INDEX('Paste BPG'!$A:$Z,MATCH($B17,'Paste BPG'!$C:$C,0),MATCH("BP LS BENDAHARA",'Paste BPG'!$3:$3,0)),".","")),0) -> 0 | F17: =IFERROR(VALUE(SUBSTITUTE(INDEX('Paste BPG'!$A:$Z,MATCH($B17,'Paste BPG'!$C:$C,0),MATCH("BP PAJAK",'Paste BPG'!$3:$3,0)),".","")),0) -> 0 | G17: =IFERROR(VALUE(SUBSTITUTE(INDEX('Paste BPG'!$A:$Z,MATCH($B17,'Paste BPG'!$C:$C,0),MATCH("BP HIBAH",'Paste BPG'!$3:$3,0)),".","")),0) -> 0 | H17: =IFERROR(VALUE(SUBSTITUTE(INDEX('Paste BPG'!$A:$Z,MATCH($B17,'Paste BPG'!$C:$C,0),MATCH("BP LAIN-LAIN",'Paste BPG'!$3:$3,0)),".","")),0) -> 0 | I17: =D17+E17+F17+G17+H17 -> 0 | J17: =D17 -> 0 | K17: =IFERROR(VALUE(SUBSTITUTE(INDEX('Paste BPG'!$A:$Z,MATCH($B17,'Paste BPG'!$C:$C,0),MATCH("KUITANSI",'Paste BPG'!$3:$3,0)),".","")),0) -> 0 | L17: =J17+K17 -> 0
A18: 11 | B18: 401957 | C18: PENGADILAN AGAMA SOREANG | D18: =IFERROR(VALUE(SUBSTITUTE(INDEX('Paste BPG'!$A:$Z,MATCH($B18,'Paste BPG'!$C:$C,0),MATCH("BP UP/TUP",'Paste BPG'!$3:$3,0)),".","")),0) -> 0 | E18: =IFERROR(VALUE(SUBSTITUTE(INDEX('Paste BPG'!$A:$Z,MATCH($B18,'Paste BPG'!$C:$C,0),MATCH("BP LS BENDAHARA",'Paste BPG'!$3:$3,0)),".","")),0) -> 0 | F18: =IFERROR(VALUE(SUBSTITUTE(INDEX('Paste BPG'!$A:$Z,MATCH($B18,'Paste BPG'!$C:$C,0),MATCH("BP PAJAK",'Paste BPG'!$3:$3,0)),".","")),0) -> 0 | G18: =IFERROR(VALUE(SUBSTITUTE(INDEX('Paste BPG'!$A:$Z,MATCH($B18,'Paste BPG'!$C:$C,0),MATCH("BP HIBAH",'Paste BPG'!$3:$3,0)),".","")),0) -> 0 | H18: =IFERROR(VALUE(SUBSTITUTE(INDEX('Paste BPG'!$A:$Z,MATCH($B18,'Paste BPG'!$C:$C,0),MATCH("BP LAIN-LAIN",'Paste BPG'!$3:$3,0)),".","")),0) -> 0 | I18: =D18+E18+F18+G18+H18 -> 0 | J18: =D18 -> 0 | K18: =IFERROR(VALUE(SUBSTITUTE(INDEX('Paste BPG'!$A:$Z,MATCH($B18,'Paste BPG'!$C:$C,0),MATCH("KUITANSI",'Paste BPG'!$3:$3,0)),".","")),0) -> 0 | L18: =J18+K18 -> 0
A19: 12 | B19: 401958 | C19: PENGADILAN AGAMA CIMAHI | D19: =IFERROR(VALUE(SUBSTITUTE(INDEX('Paste BPG'!$A:$Z,MATCH($B19,'Paste BPG'!$C:$C,0),MATCH("BP UP/TUP",'Paste BPG'!$3:$3,0)),".","")),0) -> 0 | E19: =IFERROR(VALUE(SUBSTITUTE(INDEX('Paste BPG'!$A:$Z,MATCH($B19,'Paste BPG'!$C:$C,0),MATCH("BP LS BENDAHARA",'Paste BPG'!$3:$3,0)),".","")),0) -> 0 | F19: =IFERROR(VALUE(SUBSTITUTE(INDEX('Paste BPG'!$A:$Z,MATCH($B19,'Paste BPG'!$C:$C,0),MATCH("BP PAJAK",'Paste BPG'!$3:$3,0)),".","")),0) -> 0 | G19: =IFERROR(VALUE(SUBSTITUTE(INDEX('Paste BPG'!$A:$Z,MATCH($B19,'Paste BPG'!$C:$C,0),MATCH("BP HIBAH",'Paste BPG'!$3:$3,0)),".","")),0) -> 0 | H19: =IFERROR(VALUE(SUBSTITUTE(INDEX('Paste BPG'!$A:$Z,MATCH($B19,'Paste BPG'!$C:$C,0),MATCH("BP LAIN-LAIN",'Paste BPG'!$3:$3,0)),".","")),0) -> 0 | I19: =D19+E19+F19+G19+H19 -> 0 | J19: =D19 -> 0 | K19: =IFERROR(VALUE(SUBSTITUTE(INDEX('Paste BPG'!$A:$Z,MATCH($B19,'Paste BPG'!$C:$C,0),MATCH("KUITANSI",'Paste BPG'!$3:$3,0)),".","")),0) -> 0 | L19: =J19+K19 -> 0
... A27: 20 | B27: 663272 | C27: PENGADILAN MILITER II - 09 DI BANDUNG | D27: =IFERROR(VALUE(SUBSTITUTE(INDEX('Paste BPG'!$A:$Z,MATCH($B27,'Paste BPG'!$C:$C,0),MATCH("BP UP/TUP",'Paste BPG'!$3:$3,0)),".","")),0) -> 0 | E27: =IFERROR(VALUE(SUBSTITUTE(INDEX('Paste BPG'!$A:$Z,MATCH($B27,'Paste BPG'!$C:$C,0),MATCH("BP LS BENDAHARA",'Paste BPG'!$3:$3,0)),".","")),0) -> 0 | F27: =IFERROR(VALUE(SUBSTITUTE(INDEX('Paste BPG'!$A:$Z,MATCH($B27,'Paste BPG'!$C:$C,0),MATCH("BP PAJAK",'Paste BPG'!$3:$3,0)),".","")),0) -> 0 | G27: =IFERROR(VALUE(SUBSTITUTE(INDEX('Paste BPG'!$A:$Z,MATCH($B27,'Paste BPG'!$C:$C,0),MATCH("BP HIBAH",'Paste BPG'!$3:$3,0)),".","")),0) -> 0 | H27: =IFERROR(VALUE(SUBSTITUTE(INDEX('Paste BPG'!$A:$Z,MATCH($B27,'Paste BPG'!$C:$C,0),MATCH("BP LAIN-LAIN",'Paste BPG'!$3:$3,0)),".","")),0) -> 0 | I27: =D27+E27+F27+G27+H27 -> 0 | J27: =D27 -> 0 | K27: =IFERROR(VALUE(SUBSTITUTE(INDEX('Paste BPG'!$A:$Z,MATCH($B27,'Paste BPG'!$C:$C,0),MATCH("KUITANSI",'Paste BPG'!$3:$3,0)),".","")),0) -> 0 | L27: =J27+K27 -> 0
B28: 006 | C28: KEJAKSAAN REPUBLIK INDONESIA | D28: =SUM(D29+D30+D31+D32) -> 0 | E28: =SUM(E29+E30+E31+E32) -> 0 | F28: =SUM(F29+F30+F31+F32) -> 0 | G28: =SUM(G29+G30+G31+G32) -> 0 | H28: =SUM(H29+H30+H31+H32) -> 0 | I28: =D28+E28+F28+G28+H28 -> 0 | J28: =SUM(J29+J30+J31+J32) -> 0 | K28: =SUM(K29+K30+K31+K32) -> 0 | L28: =J28+K28 -> 0
A29: 21 | B29: 005083 | C29: KEJAKSAAN TINGGI JAWA BARAT | D29: =IFERROR(VALUE(SUBSTITUTE(INDEX('Paste BPG'!$A:$Z,MATCH($B29,'Paste BPG'!$C:$C,0),MATCH("BP UP/TUP",'Paste BPG'!$3:$3,0)),".","")),0) -> 0 | E29: =IFERROR(VALUE(SUBSTITUTE(INDEX('Paste BPG'!$A:$Z,MATCH($B29,'Paste BPG'!$C:$C,0),MATCH("BP LS BENDAHARA",'Paste BPG'!$3:$3,0)),".","")),0) -> 0 | F29: =IFERROR(VALUE(SUBSTITUTE(INDEX('Paste BPG'!$A:$Z,MATCH($B29,'Paste BPG'!$C:$C,0),MATCH("BP PAJAK",'Paste BPG'!$3:$3,0)),".","")),0) -> 0 | G29: =IFERROR(VALUE(SUBSTITUTE(INDEX('Paste BPG'!$A:$Z,MATCH($B29,'Paste BPG'!$C:$C,0),MATCH("BP HIBAH",'Paste BPG'!$3:$3,0)),".","")),0) -> 0 | H29: =IFERROR(VALUE(SUBSTITUTE(INDEX('Paste BPG'!$A:$Z,MATCH($B29,'Paste BPG'!$C:$C,0),MATCH("BP LAIN-LAIN",'Paste BPG'!$3:$3,0)),".","")),0) -> 0 | I29: =D29+E29+F29+G29+H29 -> 0 | J29: =D29 -> 0 | K29: =IFERROR(VALUE(SUBSTITUTE(INDEX('Paste BPG'!$A:$Z,MATCH($B29,'Paste BPG'!$C:$C,0),MATCH("KUITANSI",'Paste BPG'!$3:$3,0)),".","")),0) -> 0 | L29: =J29+K29 -> 0
A30: 22 | B30: 005090 | C30: KEJAKSAAN NEGERI KOTA BANDUNG | D30: =IFERROR(VALUE(SUBSTITUTE(INDEX('Paste BPG'!$A:$Z,MATCH($B30,'Paste BPG'!$C:$C,0),MATCH("BP UP/TUP",'Paste BPG'!$3:$3,0)),".","")),0) -> 0 | E30: =IFERROR(VALUE(SUBSTITUTE(INDEX('Paste BPG'!$A:$Z,MATCH($B30,'Paste BPG'!$C:$C,0),MATCH("BP LS BENDAHARA",'Paste BPG'!$3:$3,0)),".","")),0) -> 0 | F30: =IFERROR(VALUE(SUBSTITUTE(INDEX('Paste BPG'!$A:$Z,MATCH($B30,'Paste BPG'!$C:$C,0),MATCH("BP PAJAK",'Paste BPG'!$3:$3,0)),".","")),0) -> 0 | G30: =IFERROR(VALUE(SUBSTITUTE(INDEX('Paste BPG'!$A:$Z,MATCH($B30,'Paste BPG'!$C:$C,0),MATCH("BP HIBAH",'Paste BPG'!$3:$3,0)),".","")),0) -> 0 | H30: =IFERROR(VALUE(SUBSTITUTE(INDEX('Paste BPG'!$A:$Z,MATCH($B30,'Paste BPG'!$C:$C,0),MATCH("BP LAIN-LAIN",'Paste BPG'!$3:$3,0)),".","")),0) -> 0 | I30: =D30+E30+F30+G30+H30 -> 0 | J30: =D30 -> 0 | K30: =IFERROR(VALUE(SUBSTITUTE(INDEX('Paste BPG'!$A:$Z,MATCH($B30,'Paste BPG'!$C:$C,0),MATCH("KUITANSI",'Paste BPG'!$3:$3,0)),".","")),0) -> 0 | L30: =J30+K30 -> 0
A31: 23 | B31: 005105 | C31: KEJAKSAAN NEGERI KABUPATEN BANDUNG | D31: =IFERROR(VALUE(SUBSTITUTE(INDEX('Paste BPG'!$A:$Z,MATCH($B31,'Paste BPG'!$C:$C,0),MATCH("BP UP/TUP",'Paste BPG'!$3:$3,0)),".","")),0) -> 0 | E31: =IFERROR(VALUE(SUBSTITUTE(INDEX('Paste BPG'!$A:$Z,MATCH($B31,'Paste BPG'!$C:$C,0),MATCH("BP LS BENDAHARA",'Paste BPG'!$3:$3,0)),".","")),0) -> 0 | F31: =IFERROR(VALUE(SUBSTITUTE(INDEX('Paste BPG'!$A:$Z,MATCH($B31,'Paste BPG'!$C:$C,0),MATCH("BP PAJAK",'Paste BPG'!$3:$3,0)),".","")),0) -> 0 | G31: =IFERROR(VALUE(SUBSTITUTE(INDEX('Paste BPG'!$A:$Z,MATCH($B31,'Paste BPG'!$C:$C,0),MATCH("BP HIBAH",'Paste BPG'!$3:$3,0)),".","")),0) -> 0 | H31: =IFERROR(VALUE(SUBSTITUTE(INDEX('Paste BPG'!$A:$Z,MATCH($B31,'Paste BPG'!$C:$C,0),MATCH("BP LAIN-LAIN",'Paste BPG'!$3:$3,0)),".","")),0) -> 0 | I31: =D31+E31+F31+G31+H31 -> 0 | J31: =D31 -> 0 | K31: =IFERROR(VALUE(SUBSTITUTE(INDEX('Paste BPG'!$A:$Z,MATCH($B31,'Paste BPG'!$C:$C,0),MATCH("KUITANSI",'Paste BPG'!$3:$3,0)),".","")),0) -> 0 | L31: =J31+K31 -> 0
A32: 24 | B32: 683017 | C32: KEJAKSAAN NEGERI CIMAHI | D32: =IFERROR(VALUE(SUBSTITUTE(INDEX('Paste BPG'!$A:$Z,MATCH($B32,'Paste BPG'!$C:$C,0),MATCH("BP UP/TUP",'Paste BPG'!$3:$3,0)),".","")),0) -> 0 | E32: =IFERROR(VALUE(SUBSTITUTE(INDEX('Paste BPG'!$A:$Z,MATCH($B32,'Paste BPG'!$C:$C,0),MATCH("BP LS BENDAHARA",'Paste BPG'!$3:$3,0)),".","")),0) -> 0 | F32: =IFERROR(VALUE(SUBSTITUTE(INDEX('Paste BPG'!$A:$Z,MATCH($B32,'Paste BPG'!$C:$C,0),MATCH("BP PAJAK",'Paste BPG'!$3:$3,0)),".","")),0) -> 0 | G32: =IFERROR(VALUE(SUBSTITUTE(INDEX('Paste BPG'!$A:$Z,MATCH($B32,'Paste BPG'!$C:$C,0),MATCH("BP HIBAH",'Paste BPG'!$3:$3,0)),".","")),0) -> 0 | H32: =IFERROR(VALUE(SUBSTITUTE(INDEX('Paste BPG'!$A:$Z,MATCH($B32,'Paste BPG'!$C:$C,0),MATCH("BP LAIN-LAIN",'Paste BPG'!$3:$3,0)),".","")),0) -> 0 | I32: =D32+E32+F32+G32+H32 -> 0 | J32: =D32 -> 0 | K32: =IFERROR(VALUE(SUBSTITUTE(INDEX('Paste BPG'!$A:$Z,MATCH($B32,'Paste BPG'!$C:$C,0),MATCH("KUITANSI",'Paste BPG'!$3:$3,0)),".","")),0) -> 0 | L32: =J32+K32 -> 0
B33: 012 | C33: KEMENTERIAN PERTAHANAN | D33: =SUM(D34+D35+D36+D37+D38+D39+D40+D41+D42+D43+D44+D45+D46+D47+D48+D49+D50+D51+D52+D53+D54+D55+D56+D57+D58+D59+D60+D61+D62+D63+D64+D65+D66+D67+D68+D69+D70+D71+D72+D73+D74+D75+D76+D77+D78+D79+D80+D81+D82+D83+D84+D85) -> 0 | E33: =SUM(E34+E35+E36+E37+E38+E39+E40+E41+E42+E43+E44+E45+E46+E47+E48+E49+E50+E51+E52+E53+E54+E55+E56+E57+E58+E59+E60+E61+E62+E63+E64+E65+E66+E67+E68+E69+E70+E71+E72+E73+E74+E75+E76+E77+E78+E79+E80+E81+E82+E83+E84+E85) -> 0 | F33: =SUM(F34+F35+F36+F37+F38+F39+F40+F41+F42+F43+F44+F45+F46+F47+F48+F49+F50+F51+F52+F53+F54+F55+F56+F57+F58+F59+F60+F61+F62+F63+F64+F65+F66+F67+F68+F69+F70+F71+F72+F73+F74+F75+F76+F77+F78+F79+F80+F81+F82+F83+F84+F85) -> 0 | G33: =SUM(G34+G35+G36+G37+G38+G39+G40+G41+G42+G43+G44+G45+G46+G47+G48+G49+G50+G51+G52+G53+G54+G55+G56+G57+G58+G59+G60+G61+G62+G63+G64+G65+G66+G67+G68+G69+G70+G71+G72+G73+G74+G75+G76+G77+G78+G79+G80+G81+G82+G83+G84+G85) -> 0 | H33: =SUM(H34+H35+H36+H37+H38+H39+H40+H41+H42+H43+H44+H45+H46+H47+H48+H49+H50+H51+H52+H53+H54+H55+H56+H57+H58+H59+H60+H61+H62+H63+H64+H65+H66+H67+H68+H69+H70+H71+H72+H73+H74+H75+H76+H77+H78+H79+H80+H81+H82+H83+H84+H85) -> 0 | I33: =D33+E33+F33+G33+H33 -> 0 | J33: =SUM(J34+J35+J36+J37+J38+J39+J40+J41+J42+J43+J44+J45+J46+J47+J48+J49+J50+J51+J52+J53+J54+J55+J56+J57+J58+J59+J60+J61+J62+J63+J64+J65+J66+J67+J68+J69+J70+J71+J72+J73+J74+J75+J76+J77+J78+J79+J80+J81+J82+J83+J84+J85) -> 0 | K33: =SUM(K34+K35+K36+K37+K38+K39+K40+K41+K42+K43+K44+K45+K46+K47+K48+K49+K50+K51+K52+K53+K54+K55+K56+K57+K58+K59+K60+K61+K62+K63+K64+K65+K66+K67+K68+K69+K70+K71+K72+K73+K74+K75+K76+K77+K78+K79+K80+K81+K82+K83+K84+K85) -> 0 | L33: =J33+K33 -> 0
A34: 25 | B34: 344202 | C34: ZIDAM III/SLW | D34: =IFERROR(VALUE(SUBSTITUTE(INDEX('Paste BPG'!$A:$Z,MATCH($B34,'Paste BPG'!$C:$C,0),MATCH("BP UP/TUP",'Paste BPG'!$3:$3,0)),".","")),0) -> 0 | E34: =IFERROR(VALUE(SUBSTITUTE(INDEX('Paste BPG'!$A:$Z,MATCH($B34,'Paste BPG'!$C:$C,0),MATCH("BP LS BENDAHARA",'Paste BPG'!$3:$3,0)),".","")),0) -> 0 | F34: =IFERROR(VALUE(SUBSTITUTE(INDEX('Paste BPG'!$A:$Z,MATCH($B34,'Paste BPG'!$C:$C,0),MATCH("BP PAJAK",'Paste BPG'!$3:$3,0)),".","")),0) -> 0 | G34: =IFERROR(VALUE(SUBSTITUTE(INDEX('Paste BPG'!$A:$Z,MATCH($B34,'Paste BPG'!$C:$C,0),MATCH("BP HIBAH",'Paste BPG'!$3:$3,0)),".","")),0) -> 0 | H34: =IFERROR(VALUE(SUBSTITUTE(INDEX('Paste BPG'!$A:$Z,MATCH($B34,'Paste BPG'!$C:$C,0),MATCH("BP LAIN-LAIN",'Paste BPG'!$3:$3,0)),".","")),0) -> 0 | I34: =D34+E34+F34+G34+H34 -> 0 | J34: =D34 -> 0 | K34: =IFERROR(VALUE(SUBSTITUTE(INDEX('Paste BPG'!$A:$Z,MATCH($B34,'Paste BPG'!$C:$C,0),MATCH("KUITANSI",'Paste BPG'!$3:$3,0)),".","")),0) -> 0 | L34: =J34+K34 -> 0
A35: 26 | B35: 344203 | C35: BEKANGDAM III/SLW | D35: =IFERROR(VALUE(SUBSTITUTE(INDEX('Paste BPG'!$A:$Z,MATCH($B35,'Paste BPG'!$C:$C,0),MATCH("BP UP/TUP",'Paste BPG'!$3:$3,0)),".","")),0) -> 0 | E35: =IFERROR(VALUE(SUBSTITUTE(INDEX('Paste BPG'!$A:$Z,MATCH($B35,'Paste BPG'!$C:$C,0),MATCH("BP LS BENDAHARA",'Paste BPG'!$3:$3,0)),".","")),0) -> 0 | F35: =IFERROR(VALUE(SUBSTITUTE(INDEX('Paste BPG'!$A:$Z,MATCH($B35,'Paste BPG'!$C:$C,0),MATCH("BP PAJAK",'Paste BPG'!$3:$3,0)),".","")),0) -> 0 | G35: =IFERROR(VALUE(SUBSTITUTE(INDEX('Paste BPG'!$A:$Z,MATCH($B35,'Paste BPG'!$C:$C,0),MATCH("BP HIBAH",'Paste BPG'!$3:$3,0)),".","")),0) -> 0 | H35: =IFERROR(VALUE(SUBSTITUTE(INDEX('Paste BPG'!$A:$Z,MATCH($B35,'Paste BPG'!$C:$C,0),MATCH("BP LAIN-LAIN",'Paste BPG'!$3:$3,0)),".","")),0) -> 0 | I35: =D35+E35+F35+G35+H35 -> 0 | J35: =D35 -> 0 | K35: =IFERROR(VALUE(SUBSTITUTE(INDEX('Paste BPG'!$A:$Z,MATCH($B35,'Paste BPG'!$C:$C,0),MATCH("KUITANSI",'Paste BPG'!$3:$3,0)),".","")),0) -> 0 | L35: =J35+K35 -> 0
A36: 27 | B36: 344204 | C36: PALDAM III/SLW | D36: =IFERROR(VALUE(SUBSTITUTE(INDEX('Paste BPG'!$A:$Z,MATCH($B36,'Paste BPG'!$C:$C,0),MATCH("BP UP/TUP",'Paste BPG'!$3:$3,0)),".","")),0) -> 0 | E36: =IFERROR(VALUE(SUBSTITUTE(INDEX('Paste BPG'!$A:$Z,MATCH($B36,'Paste BPG'!$C:$C,0),MATCH("BP LS BENDAHARA",'Paste BPG'!$3:$3,0)),".","")),0) -> 0 | F36: =IFERROR(VALUE(SUBSTITUTE(INDEX('Paste BPG'!$A:$Z,MATCH($B36,'Paste BPG'!$C:$C,0),MATCH("BP PAJAK",'Paste BPG'!$3:$3,0)),".","")),0) -> 0 | G36: =IFERROR(VALUE(SUBSTITUTE(INDEX('Paste BPG'!$A:$Z,MATCH($B36,'Paste BPG'!$C:$C,0),MATCH("BP HIBAH",'Paste BPG'!$3:$3,0)),".","")),0) -> 0 | H36: =IFERROR(VALUE(SUBSTITUTE(INDEX('Paste BPG'!$A:$Z,MATCH($B36,'Paste BPG'!$C:$C,0),MATCH("BP LAIN-LAIN",'Paste BPG'!$3:$3,0)),".","")),0) -> 0 | I36: =D36+E36+F36+G36+H36 -> 0 | J36: =D36 -> 0 | K36: =IFERROR(VALUE(SUBSTITUTE(INDEX('Paste BPG'!$A:$Z,MATCH($B36,'Paste BPG'!$C:$C,0),MATCH("KUITANSI",'Paste BPG'!$3:$3,0)),".","")),0) -> 0 | L36: =J36+K36 -> 0
A37: 28 | B37: 344205 | C37: HUBDAM III/SLW | D37: =IFERROR(VALUE(SUBSTITUTE(INDEX('Paste BPG'!$A:$Z,MATCH($B37,'Paste BPG'!$C:$C,0),MATCH("BP UP/TUP",'Paste BPG'!$3:$3,0)),".","")),0) -> 0 | E37: =IFERROR(VALUE(SUBSTITUTE(INDEX('Paste BPG'!$A:$Z,MATCH($B37,'Paste BPG'!$C:$C,0),MATCH("BP LS BENDAHARA",'Paste BPG'!$3:$3,0)),".","")),0) -> 0 | F37: =IFERROR(VALUE(SUBSTITUTE(INDEX('Paste BPG'!$A:$Z,MATCH($B37,'Paste BPG'!$C:$C,0),MATCH("BP PAJAK",'Paste BPG'!$3:$3,0)),".","")),0) -> 0 | G37: =IFERROR(VALUE(SUBSTITUTE(INDEX('Paste BPG'!$A:$Z,MATCH($B37,'Paste BPG'!$C:$C,0),MATCH("BP HIBAH",'Paste BPG'!$3:$3,0)),".","")),0) -> 0 | H37: =IFERROR(VALUE(SUBSTITUTE(INDEX('Paste BPG'!$A:$Z,MATCH($B37,'Paste BPG'!$C:$C,0),MATCH("BP LAIN-LAIN",'Paste BPG'!$3:$3,0)),".","")),0) -> 0 | I37: =D37+E37+F37+G37+H37 -> 0 | J37: =D37 -> 0 | K37: =IFERROR(VALUE(SUBSTITUTE(INDEX('Paste BPG'!$A:$Z,MATCH($B37,'Paste BPG'!$C:$C,0),MATCH("KUITANSI",'Paste BPG'!$3:$3,0)),".","")),0) -> 0 | L37: =J37+K37 -> 0
A38: 29 | B38: 344206 | C38: KESDAM III/SLW | D38: =IFERROR(VALUE(SUBSTITUTE(INDEX('Paste BPG'!$A:$Z,MATCH($B38,'Paste BPG'!$C:$C,0),MATCH("BP UP/TUP",'Paste BPG'!$3:$3,0)),".","")),0) -> 0 | E38: =IFERROR(VALUE(SUBSTITUTE(INDEX('Paste BPG'!$A:$Z,MATCH($B38,'Paste BPG'!$C:$C,0),MATCH("BP LS BENDAHARA",'Paste BPG'!$3:$3,0)),".","")),0) -> 0 | F38: =IFERROR(VALUE(SUBSTITUTE(INDEX('Paste BPG'!$A:$Z,MATCH($B38,'Paste BPG'!$C:$C,0),MATCH("BP PAJAK",'Paste BPG'!$3:$3,0)),".","")),0) -> 0 | G38: =IFERROR(VALUE(SUBSTITUTE(INDEX('Paste BPG'!$A:$Z,MATCH($B38,'Paste BPG'!$C:$C,0),MATCH("BP HIBAH",'Paste BPG'!$3:$3,0)),".","")),0) -> 0 | H38: =IFERROR(VALUE(SUBSTITUTE(INDEX('Paste BPG'!$A:$Z,MATCH($B38,'Paste BPG'!$C:$C,0),MATCH("BP LAIN-LAIN",'Paste BPG'!$3:$3,0)),".","")),0) -> 0 | I38: =D38+E38+F38+G38+H38 -> 0 | J38: =D38 -> 0 | K38: =IFERROR(VALUE(SUBSTITUTE(INDEX('Paste BPG'!$A:$Z,MATCH($B38,'Paste BPG'!$C:$C,0),MATCH("KUITANSI",'Paste BPG'!$3:$3,0)),".","")),0) -> 0 | L38: =J38+K38 -> 0
A39: 30 | B39: 344215 | C39: RINDAM III/SLW | D39: =IFERROR(VALUE(SUBSTITUTE(INDEX('Paste BPG'!$A:$Z,MATCH($B39,'Paste BPG'!$C:$C,0),MATCH("BP UP/TUP",'Paste BPG'!$3:$3,0)),".","")),0) -> 0 | E39: =IFERROR(VALUE(SUBSTITUTE(INDEX('Paste BPG'!$A:$Z,MATCH($B39,'Paste BPG'!$C:$C,0),MATCH("BP LS BENDAHARA",'Paste BPG'!$3:$3,0)),".","")),0) -> 0 | F39: =IFERROR(VALUE(SUBSTITUTE(INDEX('Paste BPG'!$A:$Z,MATCH($B39,'Paste BPG'!$C:$C,0),MATCH("BP PAJAK",'Paste BPG'!$3:$3,0)),".","")),0) -> 0 | G39: =IFERROR(VALUE(SUBSTITUTE(INDEX('Paste BPG'!$A:$Z,MATCH($B39,'Paste BPG'!$C:$C,0),MATCH("BP HIBAH",'Paste BPG'!$3:$3,0)),".","")),0) -> 0 | H39: =IFERROR(VALUE(SUBSTITUTE(INDEX('Paste BPG'!$A:$Z,MATCH($B39,'Paste BPG'!$C:$C,0),MATCH("BP LAIN-LAIN",'Paste BPG'!$3:$3,0)),".","")),0) -> 0 | I39: =D39+E39+F39+G39+H39 -> 0 | J39: =D39 -> 0 | K39: =IFERROR(VALUE(SUBSTITUTE(INDEX('Paste BPG'!$A:$Z,MATCH($B39,'Paste BPG'!$C:$C,0),MATCH("KUITANSI",'Paste BPG'!$3:$3,0)),".","")),0) -> 0 | L39: =J39+K39 -> 0
A40: 31 | B40: 344221 | C40: BRIGIF-15 /KJ DAM III/SLW | D40: =IFERROR(VALUE(SUBSTITUTE(INDEX('Paste BPG'!$A:$Z,MATCH($B40,'Paste BPG'!$C:$C,0),MATCH("BP UP/TUP",'Paste BPG'!$3:$3,0)),".","")),0) -> 0 | E40: =IFERROR(VALUE(SUBSTITUTE(INDEX('Paste BPG'!$A:$Z,MATCH($B40,'Paste BPG'!$C:$C,0),MATCH("BP LS BENDAHARA",'Paste BPG'!$3:$3,0)),".","")),0) -> 0 | F40: =IFERROR(VALUE(SUBSTITUTE(INDEX('Paste BPG'!$A:$Z,MATCH($B40,'Paste BPG'!$C:$C,0),MATCH("BP PAJAK",'Paste BPG'!$3:$3,0)),".","")),0) -> 0 | G40: =IFERROR(VALUE(SUBSTITUTE(INDEX('Paste BPG'!$A:$Z,MATCH($B40,'Paste BPG'!$C:$C,0),MATCH("BP HIBAH",'Paste BPG'!$3:$3,0)),".","")),0) -> 0 | H40: =IFERROR(VALUE(SUBSTITUTE(INDEX('Paste BPG'!$A:$Z,MATCH($B40,'Paste BPG'!$C:$C,0),MATCH("BP LAIN-LAIN",'Paste BPG'!$3:$3,0)),".","")),0) -> 0 | I40: =D40+E40+F40+G40+H40 -> 0 | J40: =D40 -> 0 | K40: =IFERROR(VALUE(SUBSTITUTE(INDEX('Paste BPG'!$A:$Z,MATCH($B40,'Paste BPG'!$C:$C,0),MATCH("KUITANSI",'Paste BPG'!$3:$3,0)),".","")),0) -> 0 | L40: =J40+K40 -> 0
A41: 32 | B41: 344507 | C41: SESKOAD | D41: =IFERROR(VALUE(SUBSTITUTE(INDEX('Paste BPG'!$A:$Z,MATCH($B41,'Paste BPG'!$C:$C,0),MATCH("BP UP/TUP",'Paste BPG'!$3:$3,0)),".","")),0) -> 0 | E41: =IFERROR(VALUE(SUBSTITUTE(INDEX('Paste BPG'!$A:$Z,MATCH($B41,'Paste BPG'!$C:$C,0),MATCH("BP LS BENDAHARA",'Paste BPG'!$3:$3,0)),".","")),0) -> 0 | F41: =IFERROR(VALUE(SUBSTITUTE(INDEX('Paste BPG'!$A:$Z,MATCH($B41,'Paste BPG'!$C:$C,0),MATCH("BP PAJAK",'Paste BPG'!$3:$3,0)),".","")),0) -> 0 | G41: =IFERROR(VALUE(SUBSTITUTE(INDEX('Paste BPG'!$A:$Z,MATCH($B41,'Paste BPG'!$C:$C,0),MATCH("BP HIBAH",'Paste BPG'!$3:$3,0)),".","")),0) -> 0 | H41: =IFERROR(VALUE(SUBSTITUTE(INDEX('Paste BPG'!$A:$Z,MATCH($B41,'Paste BPG'!$C:$C,0),MATCH("BP LAIN-LAIN",'Paste BPG'!$3:$3,0)),".","")),0) -> 0 | I41: =D41+E41+F41+G41+H41 -> 0 | J41: =D41 -> 0 | K41: =IFERROR(VALUE(SUBSTITUTE(INDEX('Paste BPG'!$A:$Z,MATCH($B41,'Paste BPG'!$C:$C,0),MATCH("KUITANSI",'Paste BPG'!$3:$3,0)),".","")),0) -> 0 | L41: =J41+K41 -> 0
A42: 33 | B42: 344513 | C42: SECAPA AD | D42: =IFERROR(VALUE(SUBSTITUTE(INDEX('Paste BPG'!$A:$Z,MATCH($B42,'Paste BPG'!$C:$C,0),MATCH("BP UP/TUP",'Paste BPG'!$3:$3,0)),".","")),0) -> 0 | E42: =IFERROR(VALUE(SUBSTITUTE(INDEX('Paste BPG'!$A:$Z,MATCH($B42,'Paste BPG'!$C:$C,0),MATCH("BP LS BENDAHARA",'Paste BPG'!$3:$3,0)),".","")),0) -> 0 | F42: =IFERROR(VALUE(SUBSTITUTE(INDEX('Paste BPG'!$A:$Z,MATCH($B42,'Paste BPG'!$C:$C,0),MATCH("BP PAJAK",'Paste BPG'!$3:$3,0)),".","")),0) -> 0 | G42: =IFERROR(VALUE(SUBSTITUTE(INDEX('Paste BPG'!$A:$Z,MATCH($B42,'Paste BPG'!$C:$C,0),MATCH("BP HIBAH",'Paste BPG'!$3:$3,0)),".","")),0) -> 0 | H42: =IFERROR(VALUE(SUBSTITUTE(INDEX('Paste BPG'!$A:$Z,MATCH($B42,'Paste BPG'!$C:$C,0),MATCH("BP LAIN-LAIN",'Paste BPG'!$3:$3,0)),".","")),0) -> 0 | I42: =D42+E42+F42+G42+H42 -> 0 | J42: =D42 -> 0 | K42: =IFERROR(VALUE(SUBSTITUTE(INDEX('Paste BPG'!$A:$Z,MATCH($B42,'Paste BPG'!$C:$C,0),MATCH("KUITANSI",'Paste BPG'!$3:$3,0)),".","")),0) -> 0 | L42: =J42+K42 -> 0
A43: 34 | B43: 344519 | C43: DITAJENAD | D43: =IFERROR(VALUE(SUBSTITUTE(INDEX('Paste BPG'!$A:$Z,MATCH($B43,'Paste BPG'!$C:$C,0),MATCH("BP UP/TUP",'Paste BPG'!$3:$3,0)),".","")),0) -> 0 | E43: =IFERROR(VALUE(SUBSTITUTE(INDEX('Paste BPG'!$A:$Z,MATCH($B43,'Paste BPG'!$C:$C,0),MATCH("BP LS BENDAHARA",'Paste BPG'!$3:$3,0)),".","")),0) -> 0 | F43: =IFERROR(VALUE(SUBSTITUTE(INDEX('Paste BPG'!$A:$Z,MATCH($B43,'Paste BPG'!$C:$C,0),MATCH("BP PAJAK",'Paste BPG'!$3:$3,0)),".","")),0) -> 0 | G43: =IFERROR(VALUE(SUBSTITUTE(INDEX('Paste BPG'!$A:$Z,MATCH($B43,'Paste BPG'!$C:$C,0),MATCH("BP HIBAH",'Paste BPG'!$3:$3,0)),".","")),0) -> 0 | H43: =IFERROR(VALUE(SUBSTITUTE(INDEX('Paste BPG'!$A:$Z,MATCH($B43,'Paste BPG'!$C:$C,0),MATCH("BP LAIN-LAIN",'Paste BPG'!$3:$3,0)),".","")),0) -> 0 | I43: =D43+E43+F43+G43+H43 -> 0 | J43: =D43 -> 0 | K43: =IFERROR(VALUE(SUBSTITUTE(INDEX('Paste BPG'!$A:$Z,MATCH($B43,'Paste BPG'!$C:$C,0),MATCH("KUITANSI",'Paste BPG'!$3:$3,0)),".","")),0) -> 0 | L43: =J43+K43 -> 0
A44: 35 | B44: 344525 | C44: DISPSIAD | D44: =IFERROR(VALUE(SUBSTITUTE(INDEX('Paste BPG'!$A:$Z,MATCH($B44,'Paste BPG'!$C:$C,0),MATCH("BP UP/TUP",'Paste BPG'!$3:$3,0)),".","")),0) -> 0 | E44: =IFERROR(VALUE(SUBSTITUTE(INDEX('Paste BPG'!$A:$Z,MATCH($B44,'Paste BPG'!$C:$C,0),MATCH("BP LS BENDAHARA",'Paste BPG'!$3:$3,0)),".","")),0) -> 0 | F44: =IFERROR(VALUE(SUBSTITUTE(INDEX('Paste BPG'!$A:$Z,MATCH($B44,'Paste BPG'!$C:$C,0),MATCH("BP PAJAK",'Paste BPG'!$3:$3,0)),".","")),0) -> 0 | G44: =IFERROR(VALUE(SUBSTITUTE(INDEX('Paste BPG'!$A:$Z,MATCH($B44,'Paste BPG'!$C:$C,0),MATCH("BP HIBAH",'Paste BPG'!$3:$3,0)),".","")),0) -> 0 | H44: =IFERROR(VALUE(SUBSTITUTE(INDEX('Paste BPG'!$A:$Z,MATCH($B44,'Paste BPG'!$C:$C,0),MATCH("BP LAIN-LAIN",'Paste BPG'!$3:$3,0)),".","")),0) -> 0 | I44: =D44+E44+F44+G44+H44 -> 0 | J44: =D44 -> 0 | K44: =IFERROR(VALUE(SUBSTITUTE(INDEX('Paste BPG'!$A:$Z,MATCH($B44,'Paste BPG'!$C:$C,0),MATCH("KUITANSI",'Paste BPG'!$3:$3,0)),".","")),0) -> 0 | L44: =J44+K44 -> 0
A45: 36 | B45: 344528 | C45: DISJASAD | D45: =IFERROR(VALUE(SUBSTITUTE(INDEX('Paste BPG'!$A:$Z,MATCH($B45,'Paste BPG'!$C:$C,0),MATCH("BP UP/TUP",'Paste BPG'!$3:$3,0)),".","")),0) -> 0 | E45: =IFERROR(VALUE(SUBSTITUTE(INDEX('Paste BPG'!$A:$Z,MATCH($B45,'Paste BPG'!$C:$C,0),MATCH("BP LS BENDAHARA",'Paste BPG'!$3:$3,0)),".","")),0) -> 0 | F45: =IFERROR(VALUE(SUBSTITUTE(INDEX('Paste BPG'!$A:$Z,MATCH($B45,'Paste BPG'!$C:$C,0),MATCH("BP PAJAK",'Paste BPG'!$3:$3,0)),".","")),0) -> 0 | G45: =IFERROR(VALUE(SUBSTITUTE(INDEX('Paste BPG'!$A:$Z,MATCH($B45,'Paste BPG'!$C:$C,0),MATCH("BP HIBAH",'Paste BPG'!$3:$3,0)),".","")),0) -> 0 | H45: =IFERROR(VALUE(SUBSTITUTE(INDEX('Paste BPG'!$A:$Z,MATCH($B45,'Paste BPG'!$C:$C,0),MATCH("BP LAIN-LAIN",'Paste BPG'!$3:$3,0)),".","")),0) -> 0 | I45: =D45+E45+F45+G45+H45 -> 0 | J45: =D45 -> 0 | K45: =IFERROR(VALUE(SUBSTITUTE(INDEX('Paste BPG'!$A:$Z,MATCH($B45,'Paste BPG'!$C:$C,0),MATCH("KUITANSI",'Paste BPG'!$3:$3,0)),".","")),0) -> 0 | L45: =J45+K45 -> 0
... A57: 48 | B57: 344872 | C57: DENMA KORPASKHAS | D57: =IFERROR(VALUE(SUBSTITUTE(INDEX('Paste BPG'!$A:$Z,MATCH($B57,'Paste BPG'!$C:$C,0),MATCH("BP UP/TUP",'Paste BPG'!$3:$3,0)),".","")),0) -> 0 | E57: =IFERROR(VALUE(SUBSTITUTE(INDEX('Paste BPG'!$A:$Z,MATCH($B57,'Paste BPG'!$C:$C,0),MATCH("BP LS BENDAHARA",'Paste BPG'!$3:$3,0)),".","")),0) -> 0 | F57: =IFERROR(VALUE(SUBSTITUTE(INDEX('Paste BPG'!$A:$Z,MATCH($B57,'Paste BPG'!$C:$C,0),MATCH("BP PAJAK",'Paste BPG'!$3:$3,0)),".","")),0) -> 0 | G57: =IFERROR(VALUE(SUBSTITUTE(INDEX('Paste BPG'!$A:$Z,MATCH($B57,'Paste BPG'!$C:$C,0),MATCH("BP HIBAH",'Paste BPG'!$3:$3,0)),".","")),0) -> 0 | H57: =IFERROR(VALUE(SUBSTITUTE(INDEX('Paste BPG'!$A:$Z,MATCH($B57,'Paste BPG'!$C:$C,0),MATCH("BP LAIN-LAIN",'Paste BPG'!$3:$3,0)),".","")),0) -> 0 | I57: =D57+E57+F57+G57+H57 -> 0 | J57: =D57 -> 0 | K57: =IFERROR(VALUE(SUBSTITUTE(INDEX('Paste BPG'!$A:$Z,MATCH($B57,'Paste BPG'!$C:$C,0),MATCH("KUITANSI",'Paste BPG'!$3:$3,0)),".","")),0) -> 0 | L57: =J57+K57 -> 0
A58: 49 | B58: 344896 | C58: RUMKIT TK. IV 03.07.03 SARININGSIH BANDUNG KESDAM III/SLW | D58: =IFERROR(VALUE(SUBSTITUTE(INDEX('Paste BPG'!$A:$Z,MATCH($B58,'Paste BPG'!$C:$C,0),MATCH("BP UP/TUP",'Paste BPG'!$3:$3,0)),".","")),0) -> 0 | E58: =IFERROR(VALUE(SUBSTITUTE(INDEX('Paste BPG'!$A:$Z,MATCH($B58,'Paste BPG'!$C:$C,0),MATCH("BP LS BENDAHARA",'Paste BPG'!$3:$3,0)),".","")),0) -> 0 | F58: =IFERROR(VALUE(SUBSTITUTE(INDEX('Paste BPG'!$A:$Z,MATCH($B58,'Paste BPG'!$C:$C,0),MATCH("BP PAJAK",'Paste BPG'!$3:$3,0)),".","")),0) -> 0 | G58: =IFERROR(VALUE(SUBSTITUTE(INDEX('Paste BPG'!$A:$Z,MATCH($B58,'Paste BPG'!$C:$C,0),MATCH("BP HIBAH",'Paste BPG'!$3:$3,0)),".","")),0) -> 0 | H58: =IFERROR(VALUE(SUBSTITUTE(INDEX('Paste BPG'!$A:$Z,MATCH($B58,'Paste BPG'!$C:$C,0),MATCH("BP LAIN-LAIN",'Paste BPG'!$3:$3,0)),".","")),0) -> 0 | I58: =D58+E58+F58+G58+H58 -> 0 | J58: =D58 -> 0 | K58: =IFERROR(VALUE(SUBSTITUTE(INDEX('Paste BPG'!$A:$Z,MATCH($B58,'Paste BPG'!$C:$C,0),MATCH("KUITANSI",'Paste BPG'!$3:$3,0)),".","")),0) -> 0
A59: 50 | B59: 684288 | C59: SESKO TNI | D59: =IFERROR(VALUE(SUBSTITUTE(INDEX('Paste BPG'!$A:$Z,MATCH($B59,'Paste BPG'!$C:$C,0),MATCH("BP UP/TUP",'Paste BPG'!$3:$3,0)),".","")),0) -> 0 | E59: =IFERROR(VALUE(SUBSTITUTE(INDEX('Paste BPG'!$A:$Z,MATCH($B59,'Paste BPG'!$C:$C,0),MATCH("BP LS BENDAHARA",'Paste BPG'!$3:$3,0)),".","")),0) -> 0 | F59: =IFERROR(VALUE(SUBSTITUTE(INDEX('Paste BPG'!$A:$Z,MATCH($B59,'Paste BPG'!$C:$C,0),MATCH("BP PAJAK",'Paste BPG'!$3:$3,0)),".","")),0) -> 0 | G59: =IFERROR(VALUE(SUBSTITUTE(INDEX('Paste BPG'!$A:$Z,MATCH($B59,'Paste BPG'!$C:$C,0),MATCH("BP HIBAH",'Paste BPG'!$3:$3,0)),".","")),0) -> 0 | H59: =IFERROR(VALUE(SUBSTITUTE(INDEX('Paste BPG'!$A:$Z,MATCH($B59,'Paste BPG'!$C:$C,0),MATCH("BP LAIN-LAIN",'Paste BPG'!$3:$3,0)),".","")),0) -> 0 | I59: =D59+E59+F59+G59+H59 -> 0 | J59: =D59 -> 0 | K59: =IFERROR(VALUE(SUBSTITUTE(INDEX('Paste BPG'!$A:$Z,MATCH($B59,'Paste BPG'!$C:$C,0),MATCH("KUITANSI",'Paste BPG'!$3:$3,0)),".","")),0) -> 0 | L59: =J59+K59 -> 0
...

Sheet Paste BPG
A1: REKAPITULASI LPJ BENDAHARA PENGELUARAN TINGKAT KPPN
A3: NO | B3: BA | C3: SATKER | D3: NAMA SATKER | E3: TGL KIRIM | F3: TGL VALIDASI KPPN | G3: TGL TOLAKAN TERAKHIR | H3: KEWAJIBAN LPJ | I3: STATUS VALIDASI | J3: BP UP/TUP | K3: BP LS BENDAHARA | L3: BP PAJAK | M3: BP HIBAH | N3: BP LAIN-LAIN | O3: JUMLAH | P3: SALDO KAS | Q3: KUITANSI | R3: JUMLAH

Sheet Report BPN
A1: DAFTAR LPJ PENERIMAAN
A2: ='Report BPG'!M2 -> BULAN JUNI TAHUN 2026
A3: KPPN BANDUNG II (095)
A4: NO | B4: KODE | C4: NAMA SATKER | D4: SALDO KAS | G4: SALDO PENERIMAAN DAN PENYETORAN
B5: SATKER | D5: KAS TUNAI | E5: KAS BANK | F5: JUMLAH | G5: SALDO AWAL | H5: PENERIMAAN | I5: PENYETORAN | J5: SALDO
B6: 005 | C6: MAHKAMAH AGUNG | D6: =SUM(D7+D8+D9+D10+D11+D12+D13+D14+D15+D16+D17+D18+D19+D20) -> 0 | E6: =SUM(E7+E8+E9+E10+E11+E12+E13+E14+E15+E16+E17+E18+E19+E20) -> 0 | F6: =D6+E6 -> 0 | G6: =SUM(G7+G8+G9+G10+G11+G12+G13+G14+G15+G16+G17+G18+G19+G20) -> 0 | H6: =SUM(H7+H8+H9+H10+H11+H12+H13+H14+H15+H16+H17+H18+H19+H20) -> 0 | I6: =SUM(I7+I8+I9+I10+I11+I12+I13+I14+I15+I16+I17+I18+I19+I20) -> 0 | J6: =G6+H6-I6+F6 -> 0
A7: 1 | B7: 097500 | C7: PENGADILAN TINGGI BANDUNG | D7: =IFERROR(VALUE(SUBSTITUTE(INDEX('Paste BPN'!$A:$Z,MATCH($B7,'Paste BPN'!$C:$C,0),MATCH("KAS TUNAI",'Paste BPN'!$3:$3,0)),".","")),0) -> 0 | E7: =IFERROR(VALUE(SUBSTITUTE(INDEX('Paste BPN'!$A:$Z,MATCH($B7,'Paste BPN'!$C:$C,0),MATCH("KAS BANK",'Paste BPN'!$3:$3,0)),".","")),0) -> 0 | F7: =D7+E7 -> 0 | G7: =IFERROR(VALUE(SUBSTITUTE(INDEX('Paste BPN'!$A:$Z,MATCH($B7,'Paste BPN'!$C:$C,0),MATCH("SALDO AWAL PNBP",'Paste BPN'!$3:$3,0)),".","")),0) -> 0 | H7: =IFERROR(VALUE(SUBSTITUTE(INDEX('Paste BPN'!$A:$Z,MATCH($B7,'Paste BPN'!$C:$C,0),MATCH("PENERIMAAN PNBP",'Paste BPN'!$3:$3,0)),".","")),0) -> 0 | I7: =IFERROR(VALUE(SUBSTITUTE(INDEX('Paste BPN'!$A:$Z,MATCH($B7,'Paste BPN'!$C:$C,0),MATCH("PENYETORAN PNBP",'Paste BPN'!$3:$3,0)),".","")),0) -> 0 | J7: =G7+H7-I7+F7 -> 0
A8: 2 | B8: 097514 | C8: PENGADILAN NEGERI BANDUNG | D8: =IFERROR(VALUE(SUBSTITUTE(INDEX('Paste BPN'!$A:$Z,MATCH($B8,'Paste BPN'!$C:$C,0),MATCH("KAS TUNAI",'Paste BPN'!$3:$3,0)),".","")),0) -> 0 | E8: =IFERROR(VALUE(SUBSTITUTE(INDEX('Paste BPN'!$A:$Z,MATCH($B8,'Paste BPN'!$C:$C,0),MATCH("KAS BANK",'Paste BPN'!$3:$3,0)),".","")),0) -> 0 | F8: =D8+E8 -> 0 | G8: =IFERROR(VALUE(SUBSTITUTE(INDEX('Paste BPN'!$A:$Z,MATCH($B8,'Paste BPN'!$C:$C,0),MATCH("SALDO AWAL PNBP",'Paste BPN'!$3:$3,0)),".","")),0) -> 0 | H8: =IFERROR(VALUE(SUBSTITUTE(INDEX('Paste BPN'!$A:$Z,MATCH($B8,'Paste BPN'!$C:$C,0),MATCH("PENERIMAAN PNBP",'Paste BPN'!$3:$3,0)),".","")),0) -> 0 | I8: =IFERROR(VALUE(SUBSTITUTE(INDEX('Paste BPN'!$A:$Z,MATCH($B8,'Paste BPN'!$C:$C,0),MATCH("PENYETORAN PNBP",'Paste BPN'!$3:$3,0)),".","")),0) -> 0 | J8: =G8+H8-I8+F8 -> 0
A9: 3 | B9: 099067 | C9: PENGADILAN TINGGI BANDUNG | D9: =IFERROR(VALUE(SUBSTITUTE(INDEX('Paste BPN'!$A:$Z,MATCH($B9,'Paste BPN'!$C:$C,0),MATCH("KAS TUNAI",'Paste BPN'!$3:$3,0)),".","")),0) -> 0 | E9: =IFERROR(VALUE(SUBSTITUTE(INDEX('Paste BPN'!$A:$Z,MATCH($B9,'Paste BPN'!$C:$C,0),MATCH("KAS BANK",'Paste BPN'!$3:$3,0)),".","")),0) -> 0 | F9: =D9+E9 -> 0 | G9: =IFERROR(VALUE(SUBSTITUTE(INDEX('Paste BPN'!$A:$Z,MATCH($B9,'Paste BPN'!$C:$C,0),MATCH("SALDO AWAL PNBP",'Paste BPN'!$3:$3,0)),".","")),0) -> 0 | H9: =IFERROR(VALUE(SUBSTITUTE(INDEX('Paste BPN'!$A:$Z,MATCH($B9,'Paste BPN'!$C:$C,0),MATCH("PENERIMAAN PNBP",'Paste BPN'!$3:$3,0)),".","")),0) -> 0 | I9: =IFERROR(VALUE(SUBSTITUTE(INDEX('Paste BPN'!$A:$Z,MATCH($B9,'Paste BPN'!$C:$C,0),MATCH("PENYETORAN PNBP",'Paste BPN'!$3:$3,0)),".","")),0) -> 0 | J9: =G9+H9-I9+F9 -> 0
A10: 4 | B10: 099068 | C10: PENGADILAN NEGERI BANDUNG | D10: =IFERROR(VALUE(SUBSTITUTE(INDEX('Paste BPN'!$A:$Z,MATCH($B10,'Paste BPN'!$C:$C,0),MATCH("KAS TUNAI",'Paste BPN'!$3:$3,0)),".","")),0) -> 0 | E10: =IFERROR(VALUE(SUBSTITUTE(INDEX('Paste BPN'!$A:$Z,MATCH($B10,'Paste BPN'!$C:$C,0),MATCH("KAS BANK",'Paste BPN'!$3:$3,0)),".","")),0) -> 0 | F10: =D10+E10 -> 0 | G10: =IFERROR(VALUE(SUBSTITUTE(INDEX('Paste BPN'!$A:$Z,MATCH($B10,'Paste BPN'!$C:$C,0),MATCH("SALDO AWAL PNBP",'Paste BPN'!$3:$3,0)),".","")),0) -> 0 | H10: =IFERROR(VALUE(SUBSTITUTE(INDEX('Paste BPN'!$A:$Z,MATCH($B10,'Paste BPN'!$C:$C,0),MATCH("PENERIMAAN PNBP",'Paste BPN'!$3:$3,0)),".","")),0) -> 0 | I10: =IFERROR(VALUE(SUBSTITUTE(INDEX('Paste BPN'!$A:$Z,MATCH($B10,'Paste BPN'!$C:$C,0),MATCH("PENYETORAN PNBP",'Paste BPN'!$3:$3,0)),".","")),0) -> 0 | J10: =G10+H10-I10+F10 -> 0
A11: 5 | B11: 308166 | C11: PENGADILAN TINGGI AGAMA BANDUNG | D11: =IFERROR(VALUE(SUBSTITUTE(INDEX('Paste BPN'!$A:$Z,MATCH($B11,'Paste BPN'!$C:$C,0),MATCH("KAS TUNAI",'Paste BPN'!$3:$3,0)),".","")),0) -> 0 | E11: =IFERROR(VALUE(SUBSTITUTE(INDEX('Paste BPN'!$A:$Z,MATCH($B11,'Paste BPN'!$C:$C,0),MATCH("KAS BANK",'Paste BPN'!$3:$3,0)),".","")),0) -> 0 | F11: =D11+E11 -> 0 | G11: =IFERROR(VALUE(SUBSTITUTE(INDEX('Paste BPN'!$A:$Z,MATCH($B11,'Paste BPN'!$C:$C,0),MATCH("SALDO AWAL PNBP",'Paste BPN'!$3:$3,0)),".","")),0) -> 0 | H11: =IFERROR(VALUE(SUBSTITUTE(INDEX('Paste BPN'!$A:$Z,MATCH($B11,'Paste BPN'!$C:$C,0),MATCH("PENERIMAAN PNBP",'Paste BPN'!$3:$3,0)),".","")),0) -> 0 | I11: =IFERROR(VALUE(SUBSTITUTE(INDEX('Paste BPN'!$A:$Z,MATCH($B11,'Paste BPN'!$C:$C,0),MATCH("PENYETORAN PNBP",'Paste BPN'!$3:$3,0)),".","")),0) -> 0 | J11: =G11+H11-I11+F11 -> 0
A12: 6 | B12: 309124 | C12: PENGADILAN TINGGI AGAMA BANDUNG | D12: =IFERROR(VALUE(SUBSTITUTE(INDEX('Paste BPN'!$A:$Z,MATCH($B12,'Paste BPN'!$C:$C,0),MATCH("KAS TUNAI",'Paste BPN'!$3:$3,0)),".","")),0) -> 0 | E12: =IFERROR(VALUE(SUBSTITUTE(INDEX('Paste BPN'!$A:$Z,MATCH($B12,'Paste BPN'!$C:$C,0),MATCH("KAS BANK",'Paste BPN'!$3:$3,0)),".","")),0) -> 0 | F12: =D12+E12 -> 0 | G12: =IFERROR(VALUE(SUBSTITUTE(INDEX('Paste BPN'!$A:$Z,MATCH($B12,'Paste BPN'!$C:$C,0),MATCH("SALDO AWAL PNBP",'Paste BPN'!$3:$3,0)),".","")),0) -> 0 | H12: =IFERROR(VALUE(SUBSTITUTE(INDEX('Paste BPN'!$A:$Z,MATCH($B12,'Paste BPN'!$C:$C,0),MATCH("PENERIMAAN PNBP",'Paste BPN'!$3:$3,0)),".","")),0) -> 0 | I12: =IFERROR(VALUE(SUBSTITUTE(INDEX('Paste BPN'!$A:$Z,MATCH($B12,'Paste BPN'!$C:$C,0),MATCH("PENYETORAN PNBP",'Paste BPN'!$3:$3,0)),".","")),0) -> 0 | J12: =G12+H12-I12+F12 -> 0
A13: 7 | B13: 400483 | C13: PENGADILAN NEGERI BALE BANDUNG | D13: =IFERROR(VALUE(SUBSTITUTE(INDEX('Paste BPN'!$A:$Z,MATCH($B13,'Paste BPN'!$C:$C,0),MATCH("KAS TUNAI",'Paste BPN'!$3:$3,0)),".","")),0) -> 0 | E13: =IFERROR(VALUE(SUBSTITUTE(INDEX('Paste BPN'!$A:$Z,MATCH($B13,'Paste BPN'!$C:$C,0),MATCH("KAS BANK",'Paste BPN'!$3:$3,0)),".","")),0) -> 0 | F13: =D13+E13 -> 0 | G13: =IFERROR(VALUE(SUBSTITUTE(INDEX('Paste BPN'!$A:$Z,MATCH($B13,'Paste BPN'!$C:$C,0),MATCH("SALDO AWAL PNBP",'Paste BPN'!$3:$3,0)),".","")),0) -> 0 | H13: =IFERROR(VALUE(SUBSTITUTE(INDEX('Paste BPN'!$A:$Z,MATCH($B13,'Paste BPN'!$C:$C,0),MATCH("PENERIMAAN PNBP",'Paste BPN'!$3:$3,0)),".","")),0) -> 0 | I13: =IFERROR(VALUE(SUBSTITUTE(INDEX('Paste BPN'!$A:$Z,MATCH($B13,'Paste BPN'!$C:$C,0),MATCH("PENYETORAN PNBP",'Paste BPN'!$3:$3,0)),".","")),0) -> 0 | J13: =G13+H13-I13+F13 -> 0
A14: 8 | B14: 400484 | C14: PENGADILAN NEGERI BALE BANDUNG | D14: =IFERROR(VALUE(SUBSTITUTE(INDEX('Paste BPN'!$A:$Z,MATCH($B14,'Paste BPN'!$C:$C,0),MATCH("KAS TUNAI",'Paste BPN'!$3:$3,0)),".","")),0) -> 0 | E14: =IFERROR(VALUE(SUBSTITUTE(INDEX('Paste BPN'!$A:$Z,MATCH($B14,'Paste BPN'!$C:$C,0),MATCH("KAS BANK",'Paste BPN'!$3:$3,0)),".","")),0) -> 0 | F14: =D14+E14 -> 0 | G14: =IFERROR(VALUE(SUBSTITUTE(INDEX('Paste BPN'!$A:$Z,MATCH($B14,'Paste BPN'!$C:$C,0),MATCH("SALDO AWAL PNBP",'Paste BPN'!$3:$3,0)),".","")),0) -> 0 | H14: =IFERROR(VALUE(SUBSTITUTE(INDEX('Paste BPN'!$A:$Z,MATCH($B14,'Paste BPN'!$C:$C,0),MATCH("PENERIMAAN PNBP",'Paste BPN'!$3:$3,0)),".","")),0) -> 0 | I14: =IFERROR(VALUE(SUBSTITUTE(INDEX('Paste BPN'!$A:$Z,MATCH($B14,'Paste BPN'!$C:$C,0),MATCH("PENYETORAN PNBP",'Paste BPN'!$3:$3,0)),".","")),0) -> 0 | J14: =G14+H14-I14+F14 -> 0
A15: 9 | B15: 400663 | C15: PENGADILAN AGAMA BANDUNG | D15: =IFERROR(VALUE(SUBSTITUTE(INDEX('Paste BPN'!$A:$Z,MATCH($B15,'Paste BPN'!$C:$C,0),MATCH("KAS TUNAI",'Paste BPN'!$3:$3,0)),".","")),0) -> 0 | E15: =IFERROR(VALUE(SUBSTITUTE(INDEX('Paste BPN'!$A:$Z,MATCH($B15,'Paste BPN'!$C:$C,0),MATCH("KAS BANK",'Paste BPN'!$3:$3,0)),".","")),0) -> 0 | F15: =D15+E15 -> 0 | G15: =IFERROR(VALUE(SUBSTITUTE(INDEX('Paste BPN'!$A:$Z,MATCH($B15,'Paste BPN'!$C:$C,0),MATCH("SALDO AWAL PNBP",'Paste BPN'!$3:$3,0)),".","")),0) -> 0 | H15: =IFERROR(VALUE(SUBSTITUTE(INDEX('Paste BPN'!$A:$Z,MATCH($B15,'Paste BPN'!$C:$C,0),MATCH("PENERIMAAN PNBP",'Paste BPN'!$3:$3,0)),".","")),0) -> 0 | I15: =IFERROR(VALUE(SUBSTITUTE(INDEX('Paste BPN'!$A:$Z,MATCH($B15,'Paste BPN'!$C:$C,0),MATCH("PENYETORAN PNBP",'Paste BPN'!$3:$3,0)),".","")),0) -> 0 | J15: =G15+H15-I15+F15 -> 0
A16: 10 | B16: 401959 | C16: PENGADILAN AGAMA NGAMPRAH | D16: =IFERROR(VALUE(SUBSTITUTE(INDEX('Paste BPN'!$A:$Z,MATCH($B16,'Paste BPN'!$C:$C,0),MATCH("KAS TUNAI",'Paste BPN'!$3:$3,0)),".","")),0) -> 0 | E16: =IFERROR(VALUE(SUBSTITUTE(INDEX('Paste BPN'!$A:$Z,MATCH($B16,'Paste BPN'!$C:$C,0),MATCH("KAS BANK",'Paste BPN'!$3:$3,0)),".","")),0) -> 0 | F16: =D16+E16 -> 0 | G16: =IFERROR(VALUE(SUBSTITUTE(INDEX('Paste BPN'!$A:$Z,MATCH($B16,'Paste BPN'!$C:$C,0),MATCH("SALDO AWAL PNBP",'Paste BPN'!$3:$3,0)),".","")),0) -> 0 | H16: =IFERROR(VALUE(SUBSTITUTE(INDEX('Paste BPN'!$A:$Z,MATCH($B16,'Paste BPN'!$C:$C,0),MATCH("PENERIMAAN PNBP",'Paste BPN'!$3:$3,0)),".","")),0) -> 0 | I16: =IFERROR(VALUE(SUBSTITUTE(INDEX('Paste BPN'!$A:$Z,MATCH($B16,'Paste BPN'!$C:$C,0),MATCH("PENYETORAN PNBP",'Paste BPN'!$3:$3,0)),".","")),0) -> 0 | J16: =G16+H16-I16+F16 -> 0
A17: 11 | B17: 403419 | C17: PENGADILAN AGAMA SOREANG | D17: =IFERROR(VALUE(SUBSTITUTE(INDEX('Paste BPN'!$A:$Z,MATCH($B17,'Paste BPN'!$C:$C,0),MATCH("KAS TUNAI",'Paste BPN'!$3:$3,0)),".","")),0) -> 0 | E17: =IFERROR(VALUE(SUBSTITUTE(INDEX('Paste BPN'!$A:$Z,MATCH($B17,'Paste BPN'!$C:$C,0),MATCH("KAS BANK",'Paste BPN'!$3:$3,0)),".","")),0) -> 0 | F17: =D17+E17 -> 0 | G17: =IFERROR(VALUE(SUBSTITUTE(INDEX('Paste BPN'!$A:$Z,MATCH($B17,'Paste BPN'!$C:$C,0),MATCH("SALDO AWAL PNBP",'Paste BPN'!$3:$3,0)),".","")),0) -> 0 | H17: =IFERROR(VALUE(SUBSTITUTE(INDEX('Paste BPN'!$A:$Z,MATCH($B17,'Paste BPN'!$C:$C,0),MATCH("PENERIMAAN PNBP",'Paste BPN'!$3:$3,0)),".","")),0) -> 0 | I17: =IFERROR(VALUE(SUBSTITUTE(INDEX('Paste BPN'!$A:$Z,MATCH($B17,'Paste BPN'!$C:$C,0),MATCH("PENYETORAN PNBP",'Paste BPN'!$3:$3,0)),".","")),0) -> 0 | J17: =G17+H17-I17+F17 -> 0
A18: 12 | B18: 403420 | C18: PENGADILAN AGAMA KOTA CIMAHI | D18: =IFERROR(VALUE(SUBSTITUTE(INDEX('Paste BPN'!$A:$Z,MATCH($B18,'Paste BPN'!$C:$C,0),MATCH("KAS TUNAI",'Paste BPN'!$3:$3,0)),".","")),0) -> 0 | E18: =IFERROR(VALUE(SUBSTITUTE(INDEX('Paste BPN'!$A:$Z,MATCH($B18,'Paste BPN'!$C:$C,0),MATCH("KAS BANK",'Paste BPN'!$3:$3,0)),".","")),0) -> 0 | F18: =D18+E18 -> 0 | G18: =IFERROR(VALUE(SUBSTITUTE(INDEX('Paste BPN'!$A:$Z,MATCH($B18,'Paste BPN'!$C:$C,0),MATCH("SALDO AWAL PNBP",'Paste BPN'!$3:$3,0)),".","")),0) -> 0 | H18: =IFERROR(VALUE(SUBSTITUTE(INDEX('Paste BPN'!$A:$Z,MATCH($B18,'Paste BPN'!$C:$C,0),MATCH("PENERIMAAN PNBP",'Paste BPN'!$3:$3,0)),".","")),0) -> 0 | I18: =IFERROR(VALUE(SUBSTITUTE(INDEX('Paste BPN'!$A:$Z,MATCH($B18,'Paste BPN'!$C:$C,0),MATCH("PENYETORAN PNBP",'Paste BPN'!$3:$3,0)),".","")),0) -> 0 | J18: =G18+H18-I18+F18 -> 0
... A20: 14 | B20: 531824 | C20: PENGADILAN TATA USAHA NEGARA BANDUNG | D20: =IFERROR(VALUE(SUBSTITUTE(INDEX('Paste BPN'!$A:$Z,MATCH($B20,'Paste BPN'!$C:$C,0),MATCH("KAS TUNAI",'Paste BPN'!$3:$3,0)),".","")),0) -> 0 | E20: =IFERROR(VALUE(SUBSTITUTE(INDEX('Paste BPN'!$A:$Z,MATCH($B20,'Paste BPN'!$C:$C,0),MATCH("KAS BANK",'Paste BPN'!$3:$3,0)),".","")),0) -> 0 | F20: =D20+E20 -> 0 | G20: =IFERROR(VALUE(SUBSTITUTE(INDEX('Paste BPN'!$A:$Z,MATCH($B20,'Paste BPN'!$C:$C,0),MATCH("SALDO AWAL PNBP",'Paste BPN'!$3:$3,0)),".","")),0) -> 0 | H20: =IFERROR(VALUE(SUBSTITUTE(INDEX('Paste BPN'!$A:$Z,MATCH($B20,'Paste BPN'!$C:$C,0),MATCH("PENERIMAAN PNBP",'Paste BPN'!$3:$3,0)),".","")),0) -> 0 | I20: =IFERROR(VALUE(SUBSTITUTE(INDEX('Paste BPN'!$A:$Z,MATCH($B20,'Paste BPN'!$C:$C,0),MATCH("PENYETORAN PNBP",'Paste BPN'!$3:$3,0)),".","")),0) -> 0 | J20: =G20+H20-I20+F20 -> 0
B21: 006 | C21: KEJAKSAAN REPUBLIK INDONESIA | D21: =SUM(D22+D23+D24+D25) -> 0 | E21: =SUM(E22+E23+E24+E25) -> 0 | F21: =SUM(F22:F25) -> 0 | G21: =SUM(G22+G23+G24+G25) -> 0 | H21: =SUM(H22+H23+H24+H25) -> 0 | I21: =SUM(I22+I23+I24+I25) -> 0 | J21: =G21+H21-I21+F21 -> 0
A22: 15 | B22: 005083 | C22: KEJAKSAAN TINGGI JAWA BARAT | D22: =IFERROR(VALUE(SUBSTITUTE(INDEX('Paste BPN'!$A:$Z,MATCH($B22,'Paste BPN'!$C:$C,0),MATCH("KAS TUNAI",'Paste BPN'!$3:$3,0)),".","")),0) -> 0 | E22: =IFERROR(VALUE(SUBSTITUTE(INDEX('Paste BPN'!$A:$Z,MATCH($B22,'Paste BPN'!$C:$C,0),MATCH("KAS BANK",'Paste BPN'!$3:$3,0)),".","")),0) -> 0 | F22: =D22+E22 -> 0 | G22: =IFERROR(VALUE(SUBSTITUTE(INDEX('Paste BPN'!$A:$Z,MATCH($B22,'Paste BPN'!$C:$C,0),MATCH("SALDO AWAL PNBP",'Paste BPN'!$3:$3,0)),".","")),0) -> 0 | H22: =IFERROR(VALUE(SUBSTITUTE(INDEX('Paste BPN'!$A:$Z,MATCH($B22,'Paste BPN'!$C:$C,0),MATCH("PENERIMAAN PNBP",'Paste BPN'!$3:$3,0)),".","")),0) -> 0 | I22: =IFERROR(VALUE(SUBSTITUTE(INDEX('Paste BPN'!$A:$Z,MATCH($B22,'Paste BPN'!$C:$C,0),MATCH("PENYETORAN PNBP",'Paste BPN'!$3:$3,0)),".","")),0) -> 0 | J22: =G22+H22-I22+F22 -> 0
A23: 16 | B23: 005090 | C23: KEJAKSAAN NEGERI KOTA BANDUNG | D23: =IFERROR(VALUE(SUBSTITUTE(INDEX('Paste BPN'!$A:$Z,MATCH($B23,'Paste BPN'!$C:$C,0),MATCH("KAS TUNAI",'Paste BPN'!$3:$3,0)),".","")),0) -> 0 | E23: =IFERROR(VALUE(SUBSTITUTE(INDEX('Paste BPN'!$A:$Z,MATCH($B23,'Paste BPN'!$C:$C,0),MATCH("KAS BANK",'Paste BPN'!$3:$3,0)),".","")),0) -> 0 | F23: =D23+E23 -> 0 | G23: =IFERROR(VALUE(SUBSTITUTE(INDEX('Paste BPN'!$A:$Z,MATCH($B23,'Paste BPN'!$C:$C,0),MATCH("SALDO AWAL PNBP",'Paste BPN'!$3:$3,0)),".","")),0) -> 0 | H23: =IFERROR(VALUE(SUBSTITUTE(INDEX('Paste BPN'!$A:$Z,MATCH($B23,'Paste BPN'!$C:$C,0),MATCH("PENERIMAAN PNBP",'Paste BPN'!$3:$3,0)),".","")),0) -> 0 | I23: =IFERROR(VALUE(SUBSTITUTE(INDEX('Paste BPN'!$A:$Z,MATCH($B23,'Paste BPN'!$C:$C,0),MATCH("PENYETORAN PNBP",'Paste BPN'!$3:$3,0)),".","")),0) -> 0 | J23: =G23+H23-I23+F23 -> 0
A24: 17 | B24: 005105 | C24: KEJAKSAAN NEGERI KABUPATEN BANDUNG | D24: =IFERROR(VALUE(SUBSTITUTE(INDEX('Paste BPN'!$A:$Z,MATCH($B24,'Paste BPN'!$C:$C,0),MATCH("KAS TUNAI",'Paste BPN'!$3:$3,0)),".","")),0) -> 0 | E24: =IFERROR(VALUE(SUBSTITUTE(INDEX('Paste BPN'!$A:$Z,MATCH($B24,'Paste BPN'!$C:$C,0),MATCH("KAS BANK",'Paste BPN'!$3:$3,0)),".","")),0) -> 0 | F24: =D24+E24 -> 0 | G24: =IFERROR(VALUE(SUBSTITUTE(INDEX('Paste BPN'!$A:$Z,MATCH($B24,'Paste BPN'!$C:$C,0),MATCH("SALDO AWAL PNBP",'Paste BPN'!$3:$3,0)),".","")),0) -> 0 | H24: =IFERROR(VALUE(SUBSTITUTE(INDEX('Paste BPN'!$A:$Z,MATCH($B24,'Paste BPN'!$C:$C,0),MATCH("PENERIMAAN PNBP",'Paste BPN'!$3:$3,0)),".","")),0) -> 0 | I24: =IFERROR(VALUE(SUBSTITUTE(INDEX('Paste BPN'!$A:$Z,MATCH($B24,'Paste BPN'!$C:$C,0),MATCH("PENYETORAN PNBP",'Paste BPN'!$3:$3,0)),".","")),0) -> 0 | J24: =G24+H24-I24+F24 -> 0
A25: 18 | B25: 683017 | C25: KEJAKSAAN NEGERI CIMAHI | D25: =IFERROR(VALUE(SUBSTITUTE(INDEX('Paste BPN'!$A:$Z,MATCH($B25,'Paste BPN'!$C:$C,0),MATCH("KAS TUNAI",'Paste BPN'!$3:$3,0)),".","")),0) -> 0 | E25: =IFERROR(VALUE(SUBSTITUTE(INDEX('Paste BPN'!$A:$Z,MATCH($B25,'Paste BPN'!$C:$C,0),MATCH("KAS BANK",'Paste BPN'!$3:$3,0)),".","")),0) -> 0 | F25: =D25+E25 -> 0 | G25: =IFERROR(VALUE(SUBSTITUTE(INDEX('Paste BPN'!$A:$Z,MATCH($B25,'Paste BPN'!$C:$C,0),MATCH("SALDO AWAL PNBP",'Paste BPN'!$3:$3,0)),".","")),0) -> 0 | H25: =IFERROR(VALUE(SUBSTITUTE(INDEX('Paste BPN'!$A:$Z,MATCH($B25,'Paste BPN'!$C:$C,0),MATCH("PENERIMAAN PNBP",'Paste BPN'!$3:$3,0)),".","")),0) -> 0 | I25: =IFERROR(VALUE(SUBSTITUTE(INDEX('Paste BPN'!$A:$Z,MATCH($B25,'Paste BPN'!$C:$C,0),MATCH("PENYETORAN PNBP",'Paste BPN'!$3:$3,0)),".","")),0) -> 0 | J25: =G25+H25-I25+F25 -> 0
B26: 12 | C26: KEMENTERIAN PERTAHANAN | D26: =SUM(D27:D29) -> 0 | E26: =SUM(E27:E29) -> 0 | F26: =D26+E26 -> 0 | G26: =SUM(G27:G29) -> 0 | H26: =SUM(H27+H29) -> 0 | I26: =SUM(I27+I29) -> 0 | J26: =G26+H26-I26+F26 -> 0
A27: 19 | B27: 344206 | C27: KESDAM III/SLW | D27: =IFERROR(VALUE(SUBSTITUTE(INDEX('Paste BPN'!$A:$Z,MATCH($B27,'Paste BPN'!$C:$C,0),MATCH("KAS TUNAI",'Paste BPN'!$3:$3,0)),".","")),0) -> 0 | E27: =IFERROR(VALUE(SUBSTITUTE(INDEX('Paste BPN'!$A:$Z,MATCH($B27,'Paste BPN'!$C:$C,0),MATCH("KAS BANK",'Paste BPN'!$3:$3,0)),".","")),0) -> 0 | F27: =D27+E27 -> 0 | G27: =IFERROR(VALUE(SUBSTITUTE(INDEX('Paste BPN'!$A:$Z,MATCH($B27,'Paste BPN'!$C:$C,0),MATCH("SALDO AWAL PNBP",'Paste BPN'!$3:$3,0)),".","")),0) -> 0 | H27: =IFERROR(VALUE(SUBSTITUTE(INDEX('Paste BPN'!$A:$Z,MATCH($B27,'Paste BPN'!$C:$C,0),MATCH("PENERIMAAN PNBP",'Paste BPN'!$3:$3,0)),".","")),0) -> 0 | I27: =IFERROR(VALUE(SUBSTITUTE(INDEX('Paste BPN'!$A:$Z,MATCH($B27,'Paste BPN'!$C:$C,0),MATCH("PENYETORAN PNBP",'Paste BPN'!$3:$3,0)),".","")),0) -> 0 | J27: =G27+H27-I27+F27 -> 0
A28: 20 | B28: 344805 | C28: LAFIAU | D28: =IFERROR(VALUE(SUBSTITUTE(INDEX('Paste BPN'!$A:$Z,MATCH($B28,'Paste BPN'!$C:$C,0),MATCH("KAS TUNAI",'Paste BPN'!$3:$3,0)),".","")),0) -> 0 | E28: =IFERROR(VALUE(SUBSTITUTE(INDEX('Paste BPN'!$A:$Z,MATCH($B28,'Paste BPN'!$C:$C,0),MATCH("KAS BANK",'Paste BPN'!$3:$3,0)),".","")),0) -> 0 | F28: =D28+E28 -> 0 | G28: =IFERROR(VALUE(SUBSTITUTE(INDEX('Paste BPN'!$A:$Z,MATCH($B28,'Paste BPN'!$C:$C,0),MATCH("SALDO AWAL PNBP",'Paste BPN'!$3:$3,0)),".","")),0) -> 0 | H28: =IFERROR(VALUE(SUBSTITUTE(INDEX('Paste BPN'!$A:$Z,MATCH($B28,'Paste BPN'!$C:$C,0),MATCH("PENERIMAAN PNBP",'Paste BPN'!$3:$3,0)),".","")),0) -> 0 | I28: =IFERROR(VALUE(SUBSTITUTE(INDEX('Paste BPN'!$A:$Z,MATCH($B28,'Paste BPN'!$C:$C,0),MATCH("PENYETORAN PNBP",'Paste BPN'!$3:$3,0)),".","")),0) -> 0 | J28: =G28+H28-I28+F28 -> 0
A29: 21 | B29: 344896 | C29: RUMKIT TK. IV 03.07.03 SARININGSIH BANDUNG KESDAM III/SLW | D29: =IFERROR(VALUE(SUBSTITUTE(INDEX('Paste BPN'!$A:$Z,MATCH($B29,'Paste BPN'!$C:$C,0),MATCH("KAS TUNAI",'Paste BPN'!$3:$3,0)),".","")),0) -> 0 | E29: =IFERROR(VALUE(SUBSTITUTE(INDEX('Paste BPN'!$A:$Z,MATCH($B29,'Paste BPN'!$C:$C,0),MATCH("KAS BANK",'Paste BPN'!$3:$3,0)),".","")),0) -> 0 | F29: =D29+E29 -> 0 | G29: =IFERROR(VALUE(SUBSTITUTE(INDEX('Paste BPN'!$A:$Z,MATCH($B29,'Paste BPN'!$C:$C,0),MATCH("SALDO AWAL PNBP",'Paste BPN'!$3:$3,0)),".","")),0) -> 0 | H29: =IFERROR(VALUE(SUBSTITUTE(INDEX('Paste BPN'!$A:$Z,MATCH($B29,'Paste BPN'!$C:$C,0),MATCH("PENERIMAAN PNBP",'Paste BPN'!$3:$3,0)),".","")),0) -> 0 | I29: =IFERROR(VALUE(SUBSTITUTE(INDEX('Paste BPN'!$A:$Z,MATCH($B29,'Paste BPN'!$C:$C,0),MATCH("PENYETORAN PNBP",'Paste BPN'!$3:$3,0)),".","")),0) -> 0 | J29: =G29+H29-I29+F29 -> 0
B30: 022 | C30: KEMENTERIAN PERHUBUNGAN | D30: =SUM(D31:D32) -> 0 | E30: =SUM(E31:E32) -> 0 | F30: =D30+E30 -> 0 | G30: =SUM(G31:G32) -> 0 | H30: =SUM(H31+H32) -> 0 | I30: =SUM(I31+I32) -> 0 | J30: =G30+H30-I30+F30 -> 0
A31: 22 | B31: 403849 | C31: BALAI PENGELOLA TRANSPORTASI DARAT WILAYAH IX | D31: =IFERROR(VALUE(SUBSTITUTE(INDEX('Paste BPN'!$A:$Z,MATCH($B31,'Paste BPN'!$C:$C,0),MATCH("KAS TUNAI",'Paste BPN'!$3:$3,0)),".","")),0) -> 0 | E31: =IFERROR(VALUE(SUBSTITUTE(INDEX('Paste BPN'!$A:$Z,MATCH($B31,'Paste BPN'!$C:$C,0),MATCH("KAS BANK",'Paste BPN'!$3:$3,0)),".","")),0) -> 0 | F31: =D31+E31 -> 0 | G31: =IFERROR(VALUE(SUBSTITUTE(INDEX('Paste BPN'!$A:$Z,MATCH($B31,'Paste BPN'!$C:$C,0),MATCH("SALDO AWAL PNBP",'Paste BPN'!$3:$3,0)),".","")),0) -> 0 | H31: =IFERROR(VALUE(SUBSTITUTE(INDEX('Paste BPN'!$A:$Z,MATCH($B31,'Paste BPN'!$C:$C,0),MATCH("PENERIMAAN PNBP",'Paste BPN'!$3:$3,0)),".","")),0) -> 0 | I31: =IFERROR(VALUE(SUBSTITUTE(INDEX('Paste BPN'!$A:$Z,MATCH($B31,'Paste BPN'!$C:$C,0),MATCH("PENYETORAN PNBP",'Paste BPN'!$3:$3,0)),".","")),0) -> 0 | J31: =G31+H31-I31+F31 -> 0
A32: 23 | B32: 419173 | C32: BALAI PENDIDIKAN DAN PELATIHAN PEMBANGUNAN KARAKTER SUMBER DAYA MANUSIA TRANSPORTASI | D32: =IFERROR(VALUE(SUBSTITUTE(INDEX('Paste BPN'!$A:$Z,MATCH($B32,'Paste BPN'!$C:$C,0),MATCH("KAS TUNAI",'Paste BPN'!$3:$3,0)),".","")),0) -> 0 | E32: =IFERROR(VALUE(SUBSTITUTE(INDEX('Paste BPN'!$A:$Z,MATCH($B32,'Paste BPN'!$C:$C,0),MATCH("KAS BANK",'Paste BPN'!$3:$3,0)),".","")),0) -> 0 | F32: =D32+E32 -> 0 | G32: =IFERROR(VALUE(SUBSTITUTE(INDEX('Paste BPN'!$A:$Z,MATCH($B32,'Paste BPN'!$C:$C,0),MATCH("SALDO AWAL PNBP",'Paste BPN'!$3:$3,0)),".","")),0) -> 0 | H32: =IFERROR(VALUE(SUBSTITUTE(INDEX('Paste BPN'!$A:$Z,MATCH($B32,'Paste BPN'!$C:$C,0),MATCH("PENERIMAAN PNBP",'Paste BPN'!$3:$3,0)),".","")),0) -> 0 | I32: =IFERROR(VALUE(SUBSTITUTE(INDEX('Paste BPN'!$A:$Z,MATCH($B32,'Paste BPN'!$C:$C,0),MATCH("PENYETORAN PNBP",'Paste BPN'!$3:$3,0)),".","")),0) -> 0 | J32: =G32+H32-I32+F32 -> 0
B33: 029 | C33: KEMENTERIAN LINGKUNGAN HIDUP DAN KEHUTANAN | D33: =D34 -> 0 | E33: =E34 -> 0 | F33: =F34 -> 0 | G33: =G34 -> 0 | H33: =H34 -> 0 | I33: =I34 -> 0 | J33: =G33+H33-I33+F33 -> 0
A34: 24 | B34: 693579 | C34: BALAI BESAR KONSERVASI SUMBER DAYA ALAM JAWA BARAT | D34: =IFERROR(VALUE(SUBSTITUTE(INDEX('Paste BPN'!$A:$Z,MATCH($B34,'Paste BPN'!$C:$C,0),MATCH("KAS TUNAI",'Paste BPN'!$3:$3,0)),".","")),0) -> 0 | E34: =IFERROR(VALUE(SUBSTITUTE(INDEX('Paste BPN'!$A:$Z,MATCH($B34,'Paste BPN'!$C:$C,0),MATCH("KAS BANK",'Paste BPN'!$3:$3,0)),".","")),0) -> 0 | F34: =D34+E34 -> 0 | G34: =IFERROR(VALUE(SUBSTITUTE(INDEX('Paste BPN'!$A:$Z,MATCH($B34,'Paste BPN'!$C:$C,0),MATCH("SALDO AWAL PNBP",'Paste BPN'!$3:$3,0)),".","")),0) -> 0 | H34: =IFERROR(VALUE(SUBSTITUTE(INDEX('Paste BPN'!$A:$Z,MATCH($B34,'Paste BPN'!$C:$C,0),MATCH("PENERIMAAN PNBP",'Paste BPN'!$3:$3,0)),".","")),0) -> 0 | I34: =IFERROR(VALUE(SUBSTITUTE(INDEX('Paste BPN'!$A:$Z,MATCH($B34,'Paste BPN'!$C:$C,0),MATCH("PENYETORAN PNBP",'Paste BPN'!$3:$3,0)),".","")),0) -> 0 | J34: =G34+H34-I34+F34 -> 0
B35: 086 | C35: LEMBAGA ADMINISTRASI NEGARA | D35: =D36+D37 -> 0 | E35: =E36+E37 -> 0 | F35: =D35+E35 -> 0 | G35: =G36+G37 -> 0 | H35: =H36+H37 -> 0 | I35: =I36+I37 -> 0 | J35: =G35+H35-I35+F35 -> 0
A36: 25 | B36: 450423 | C36: PUSAT PELATIHAN DAN PENGEMBANGAN DAN PEMETAAN KOMPETENSI ASN | D36: =IFERROR(VALUE(SUBSTITUTE(INDEX('Paste BPN'!$A:$Z,MATCH($B36,'Paste BPN'!$C:$C,0),MATCH("KAS TUNAI",'Paste BPN'!$3:$3,0)),".","")),0) -> 0 | E36: =IFERROR(VALUE(SUBSTITUTE(INDEX('Paste BPN'!$A:$Z,MATCH($B36,'Paste BPN'!$C:$C,0),MATCH("KAS BANK",'Paste BPN'!$3:$3,0)),".","")),0) -> 0 | F36: =D36+E36 -> 0 | G36: =IFERROR(VALUE(SUBSTITUTE(INDEX('Paste BPN'!$A:$Z,MATCH($B36,'Paste BPN'!$C:$C,0),MATCH("SALDO AWAL PNBP",'Paste BPN'!$3:$3,0)),".","")),0) -> 0 | H36: =IFERROR(VALUE(SUBSTITUTE(INDEX('Paste BPN'!$A:$Z,MATCH($B36,'Paste BPN'!$C:$C,0),MATCH("PENERIMAAN PNBP",'Paste BPN'!$3:$3,0)),".","")),0) -> 0 | I36: =IFERROR(VALUE(SUBSTITUTE(INDEX('Paste BPN'!$A:$Z,MATCH($B36,'Paste BPN'!$C:$C,0),MATCH("PENYETORAN PNBP",'Paste BPN'!$3:$3,0)),".","")),0) -> 0 | J36: =G36+H36-I36+F36 -> 0
A37: 26 | B37: 662635 | C37: STIA-LAN BANDUNG | D37: =IFERROR(VALUE(SUBSTITUTE(INDEX('Paste BPN'!$A:$Z,MATCH($B37,'Paste BPN'!$C:$C,0),MATCH("KAS TUNAI",'Paste BPN'!$3:$3,0)),".","")),0) -> 0 | E37: =IFERROR(VALUE(SUBSTITUTE(INDEX('Paste BPN'!$A:$Z,MATCH($B37,'Paste BPN'!$C:$C,0),MATCH("KAS BANK",'Paste BPN'!$3:$3,0)),".","")),0) -> 0 | F37: =D37+E37 -> 0 | G37: =IFERROR(VALUE(SUBSTITUTE(INDEX('Paste BPN'!$A:$Z,MATCH($B37,'Paste BPN'!$C:$C,0),MATCH("SALDO AWAL PNBP",'Paste BPN'!$3:$3,0)),".","")),0) -> 0 | H37: =IFERROR(VALUE(SUBSTITUTE(INDEX('Paste BPN'!$A:$Z,MATCH($B37,'Paste BPN'!$C:$C,0),MATCH("PENERIMAAN PNBP",'Paste BPN'!$3:$3,0)),".","")),0) -> 0 | I37: =IFERROR(VALUE(SUBSTITUTE(INDEX('Paste BPN'!$A:$Z,MATCH($B37,'Paste BPN'!$C:$C,0),MATCH("PENYETORAN PNBP",'Paste BPN'!$3:$3,0)),".","")),0) -> 0 | J37: =G37+H37-I37+F37 -> 0
